Workbook

Sheet Basic Prices
A1: BASIC PRICES
A4: Trade | B4: Materials | E4: Labour | H4: Plant
B5: Description | C5: Unit | D5: Basic Price | E5: Description | F5: Unit | G5: Basic Price | H5: Description | I5: Unit | J5: Basic Price
A6: EXCAVATION | B6: Dry hard earth with transport cost | C6: cube. | E6: Skilled | F6: day | G6: 2500 | H6: Tractor
A7: EXCAVATION | B7: Quarry dust with transport cost | C7: cube.
A8: EXCAVATION | B8: 1 1/2" thick plank (class 11) | C8: S. ft | E8: Un skilled | F8: day | G8: 2000
A9: EXCAVATION | B9: 2" x 4" joist (class 11) | C9: L. ft
A10: EXCAVATION | B10: 2" x 6" joist (class 11) | C10: L. ft
A11: EXCAVATION | B11: Wire nails | C11: kg.
A12: CONCRETE | B12: Cement | C12: bag | D12: 1850 | E12: Skilled Labour | F12: day | G12: 2500 | H12: Concrete Mixer | J12: 2000
A13: CONCRETE | B13: Sand | C13: cube. | D13: 15000 | E13: Un Skilled Labour | F13: day | G13: 2000 | H13: Vibrator | J13: 1500
A14: CONCRETE | B14: Metal 3/4 " | C14: cube. | D14: 12000 | E14: Vibrator Operator | F14: day | G14: 2000
A15: CONCRETE | B15: Metal 1 " | C15: cube. | E15: Concrete Mixer operator | F15: day | G15: 2000
A16: CONCRETE | B16: Metal 2 " | C16: cube.
A17: CONCRETE | B17: Water | C17: gal.
A18: FORM WORK | B18: 1" thick plank class 11 | C18: S. ft | E18: Skilled Labour | F18: day | G18: =$G$6 -> 2500
A19: FORM WORK | B19: 2 " x 4 " class 11 | C19: L. ft | E19: Un Skilled Labour | F19: day | G19: =$G$8 -> 2000
A20: FORM WORK | B20: 2 " x 2 " class 11 | C20: L. ft
A21: FORM WORK | B21: 2 " x 1 " class 11 | C21: L. ft
A22: FORM WORK | B22: Wire nails | C22: kg.
A23: FORM WORK | B23: Mould oil | C23: ltr
A24: FORM WORK | B24: 16mm bolt | C24: Nr
A25: REINFORCEMENT | B25: Tor Steel | E25: Skilled labour | F25: day | G25: 700
A26: REINFORCEMENT | B26: 25mm | C26: kg. | E26: Un skilled labour | F26: day | G26: 450
A27: REINFORCEMENT | B27: 20mm | C27: kg.
A28: REINFORCEMENT | B28: 16mm | C28: kg.
A29: REINFORCEMENT | B29: 12mm | C29: kg.
A30: REINFORCEMENT | B30: 10mm | C30: kg.
A31: REINFORCEMENT | B31: binding wire | C31: kg.
A32: REINFORCEMENT | B32: Mild steel
A33: REINFORCEMENT | B33: 10mm | C33: kg.
A34: REINFORCEMENT | B34: 6mm | C34: kg.
A35: RUBBLE & CEMENT BLOCKS | B35: Rubble | C35: cube. | D35: 5000 | E35: Skilled labour | F35: day | G35: 2500
A36: RUBBLE & CEMENT BLOCKS | B36: cement | C36: bag | D36: 1850 | E36: Un skilled labour | F36: day | G36: 2000
A37: RUBBLE & CEMENT BLOCKS | B37: sand | C37: cube. | D37: 15000
A38: RUBBLE & CEMENT BLOCKS | B38: water | C38: gal.
A39: RUBBLE & CEMENT BLOCKS | B39: 8" thick cemrnt hollow block | C39: Nr
A40: RUBBLE & CEMENT BLOCKS | B40: 6" thick cemrnt hollow block | C40: Nr | D40: 65
A41: RUBBLE & CEMENT BLOCKS | B41: 4" hick cemrnt hollow block | C41: Nr
A42: BRICK WORK | B42: Cement | C42: bag | D42: 1850 | E42: Skilled Labour | F42: day | G42: 2500
...

Sheet Basic Rates
A1: Basic Prices
A2: MATERIALS | F2: LABOUR | K2: PLANT
A3: Item No. | B3: Description | C3: Code No. | D3: Unit | E3: Price ( Rs.) | F3: Item No. | G3: Description | H3: Code No. | I3: Unit | J3: Price ( Rs.) | K3: Item No. | L3: Description | M3: Code No. | N3: Unit | O3: Price ( Rs.)
A4: 1 | B4: Acid | C4: M-001 | D4: Gal | E4: 254 | F4: 1 | G4: Painter | H4: L-001 | I4: Day | J4: 4000 | K4: 1 | L4: Hire of Mixer | M4: P-001 | N4: Day | O4: 5000
A5: 2 | B5: Anti Corrosive Primer | C5: M-002 | D5: litre | E5: 4180 | F5: 2 | G5: Plumber | H5: L-002 | I5: Day | J5: 3500 | K5: 2 | L5: Hire of Vibrator | M5: P-002 | N5: Day | O5: 2500
A6: 3 | B6: Asbestos Corrugated Sheet | C6: M-003 | D6: Sq.ft | E6: 26 | F6: 3 | G6: SK Labour | H6: L-003 | I6: Day | J6: 3500 | K6: 3 | L6: Vibrating Rammer | M6: P-003 | N6: Day | O6: 3000
A7: 4 | B7: Barrel Bolt | C7: M-004 | D7: No | E7: 75 | F7: 4 | G7: SK Labour (Vibrator) | H7: L-004 | I7: Day | J7: 3500
A8: 5 | B8: Binding Wire - 16 BW | C8: M-005 | D8: Lbs | E8: 560 | F8: 5 | G8: Tinker | H8: L-005 | I8: Day | J8: 3500
A9: 6 | B9: Bitumen | C9: M-006 | D9: Gal | E9: 80 | F9: 6 | G9: Tiler | H9: L-006 | I9: Day | J9: 4000
A10: 7 | B10: Blasting Powder | C10: M-007 | D10: Lbs | E10: 200 | F10: 7 | G10: U / SK Labourer | H10: L-007 | I10: Day | J10: 2300
A11: 8 | B11: Blue | C11: M-008 | D11: Ozs | E11: 10 | F11: 8 | G11: Carpenter | H11: L-008 | I11: Day | J11: 3500
A12: 9 | B12: Boild Lime | C12: M-009 | D12: Cwt | E12: 300 | F12: 9 | G12: Mason | H12: L-009 | I12: Day | J12: 3500
A13: 10 | B13: Bolts 16mm 18" | C13: M-010 | D13: No | E13: 75 | F13: 10 | G13: Glazier | H13: L-010 | I13: Day | J13: 2000
A14: 11 | B14: Brass Fanlight Chtches | C14: M-011 | D14: No | E14: 45
A15: 12 | B15: Brass Nails - 1 1/2" | C15: M-012 | D15: Lbs | E15: 50
A16: 13 | B16: Brass Pannel Pins | C16: M-013 | D16: Doz | E16: 1
A17: 14 | B17: Brass scews - 1" | C17: M-014 | D17: No | E17: 2.5
A18: 15 | B18: Brass Screws 1 1/2" | C18: M-015 | D18: No | E18: 3.75
A19: 16 | B19: Brass Screws - 1/2 " | C19: M-016 | D19: No | E19: 1.3
A20: 17 | B20: Brass Screws - 3/4" | C20: M-017 | D20: No | E20: 7
A21: 18 | B21: Brass Screws - 4" Long | C21: M-018 | D21: No | E21: 7.5
A22: 19 | B22: Bricks | C22: M-019 | D22: No | E22: 20
A23: 20 | B23: Brush - 3" | C23: M-020 | D23: No | E23: 1200
A24: 21 | B24: Brush - 6" | C24: M-021 | D24: No | E24: 2350
A25: 22 | B25: Brush 2" | C25: M-022 | D25: No | E25: 900
... A56: 53 | B56: Gravel delivered to site | C56: M-053 | D56: Cube | E56: 2000
A57: 54 | B57: Gutter Brackets | C57: M-054 | D57: No
A58: 55 | B58: Gutter joiner | C58: M-055 | D58: No
A59: 56 | B59: Half Round Clay Tiles | C59: M-056 | D59: No | E59: 5
A60: 57 | B60: Hollow Cement Block - 8" thk. | C60: M-057 | D60: No | E60: 180
A61: 58 | B61: Hollow Cement Blocks - 4" thk. | C61: M-058 | D61: No | E61: 100
A62: 59 | B62: Hollow Cement Blocks - 6" thk. | C62: M-059 | D62: No | E62: 160
A63: 60 | B63: Iron Nails - 1 1/2 | C63: M-060 | D63: Kg. | E63: 25
A64: 61 | B64: Iron Screws - 3/4" | C64: M-061 | D64: No | E64: 0.55
A65: 62 | B65: Jumper Steel | C65: M-062 | D65: Lbs | E65: 65
A66: 63 | B66: Jute Hessian | C66: M-063 | D66: Sq.ft | E66: 3.5
A67: 64 | B67: Metal - 1 " | C67: M-064 | D67: Cube | E67: 12000
A68: 65 | B68: Metal - 1 1/2 " | C68: M-065 | D68: Cube | E68: 9000
A69: 66 | B69: Metal - 3/4 " | C69: M-066 | D69: Cube | E69: 15000
A70: 67 | B70: Mild Steel Dowels - 5/8" , 4" Long. | C70: M-067 | D70: No | E70: 6
...

Sheet Activity
B1: Activity
B2: 1 | C2: Site Preparation & Excavation
B3: 2 | C3: Earth work support and Filling
B4: 3 | C4: Anti Termite Treatment & DPC
B5: 4 | C5: Random Rubble Masonry Work
B6: 5 | C6: Concrete Work
B7: 6 | C7: Formwork | F7: Note
B8: 7 | C8: Reinforcement | F8: Rate Break Downs of all trades are according to the Building Schedule of Rates of the Department of Buildings except the Rate Break Downs of Concrete Works
B9: 8 | C9: Block Work
B10: 9 | C10: Brick Work
B11: 10 | C11: Roof
B12: 11 | C12: Doors and Windows
B13: 12 | C13: Plumbing & Drainage
B14: 13 | C14: Plastering
B15: 14 | C15: Tiling
B16: 15 | C16: Ceiling
B17: 16 | C17: Painting

Sheet 01
A2: 01. Site Preparation & Excavation
B4: A. | C4: Site Preparation
B5: B. | C5: Excavation
A7: Site Preparation
A9: 01.A. 01 | C9: Clearing site and grubbing up all small trees not exceeding 500mm girth and including bushes, scrubs, undergrowth hedges etc.
E10: Analysis for | F10: 1 | G10: Sqr
B11: No. | C11: Item Description | D11: Item Ref | E11: Unit | F11: Quantity | G11: Rate | H11: Amount
B12: 1 | C12: U / SK Labourer | D12: L-007 | E12: Day | F12: 0.75 | G12: ='Basic Rates'!J10 -> 2300 | H12: =G12*F12 -> 1725
B13: 1.01 | C13: Allow 2.5% of Items ( 1.01 ) for Tools | H13: =H12*2.5/100 -> 43.125
D14: Total for | E14: 1 | F14: =G10 -> Sqr | H14: =SUM(H12:H13) -> 1768.125
D15: Rate for 1 | E15: =$G$34 -> Sqrs | H15: =H14/F10 -> 1768.125
D16: Rate(Say) | G16: 1Sqr | H16: =H15 -> 1768.125
D17: Rate(Say) | G17: 1ft2 | H17: =H16/100 -> 17.68125
D18: Rate(Say) | G18: 1m2 | H18: =H17*10.76 -> 190.25025
A20: 01.A.02 | C20: Cutting turf Sods, loading to hand carts and transporting up to 30 Yards, laying and watering for 30 days(Royalty for Turf, pegging, transporting beyond 30yds paid separately)
E21: Analysis for | F21: 1 | G21: Sqr
B22: No | C22: Item Description | D22: Item Ref | E22: Unit | F22: Quantity | G22: Rate | H22: Amount
B23: 1.01 | C23: U / SK Labourer - cutting turf sods, loading & unloading | D23: L-007 | E23: Day | F23: 2.5 | G23: ='Basic Rates'!J10 -> 2300 | H23: =F23*G23 -> 5750
B24: 1.02 | C24: U / SK Labourer - laying turf sods | D24: L-007 | E24: Day | F24: 0.5 | G24: =G23 -> 2300 | H24: =F24*G24 -> 1150
B25: 1.03 | C25: U / SK Labourer - watering | D25: L-007 | E25: Day | F25: 1.5 | G25: =G23 -> 2300 | H25: =F25*G25 -> 3450
B26: 1.04 | C26: Water | D26: M-157 | E26: Gal | F26: 60 | G26: ='Basic Rates'!E161 -> 0.3 | H26: =F26*G26 -> 18
D27: Total for | E27: =$F$21 -> 1 | F27: =$G$21 -> Sqr | H27: =SUM(H23:H26) -> 10368
D28: Rate for 1 | E28: =$G$21 -> Sqr | H28: =H27/F21 -> 10368
D29: Rate(Say) | G29: 1Sqr | H29: =H28 -> 10368
D30: Rate(Say) | G30: 1ft2 | H30: =H29/100 -> 103.68
D31: Rate(Say) | G31: 1m2 | H31: =H30*10.76 -> 1115.5968
A33: 01.A.03 | C33: Removing top soil to a Depth not Exceeding 6" & Depositing as Directed within Site
E34: Analysis for | F34: 10 | G34: Sqrs
B35: No. | C35: Item Description | D35: Item Ref | E35: Unit | F35: Quantity | G35: Rate | H35: Amount
B36: 1 | C36: U / SK Labourer | D36: L-007 | E36: Day | F36: 10 | G36: =G23 -> 2300 | H36: =G36*F36 -> 23000
B37: 1.01 | C37: Allow 2.5% of Items ( 1.01 ) for Tools | H37: =H36*2.5/100 -> 575
D38: Total for | E38: =$F$34 -> 10 | F38: =$G$34 -> Sqrs | H38: =SUM(H36:H37) -> 23575
D39: Rate for 1 | E39: =$G$34 -> Sqrs | H39: =H38/F34 -> 2357.5
D40: Rate(Say) | G40: 1Sqr | H40: =H39 -> 2357.5
D41: Rate(Say) | G41: 1ft2 | H41: =H40/100 -> 23.575
D42: Rate(Say) | G42: 1m2 | H42: =H41*10.76 -> 253.667
A44: Excavation
A46: 01.B.01 | C46: Excavation over site to reduce level, in any material except rock requiring blasting including depositing and levelling as directed upto a distance not exceeding 30' 0 "
E47: Analysis for | F47: 1 | G47: Cube
B48: No. | C48: Item Description | D48: Item Ref | E48: Unit | F48: Quantity | G48: Rate | H48: Amount
...

Sheet 02
A2: 02. Filling and Earth Work Support
B3: A. | C3: Filling
B4: B. | C4: Earthwork Support
A6: Backfilling
A8: 02.A.01 | C8: Backfilling to trenches with selected earth available at site.
E9: Analysis for | F9: 1 | G9: Cube
B10: No | C10: Item Description | D10: Item Ref | E10: Unit | F10: Quantity | G10: Rate | H10: Amount
B11: 1 | C11: U / SK Labourer | D11: L-007 | E11: Day | F11: 1 | G11: ='Basic Rates'!J10 -> 2300 | H11: =F11*G11 -> 2300
B12: 1.02 | C12: Allow 2.5% of Items ( 1 ) for Tools | H12: =H11*2.5/100 -> 57.5
D13: Total for | E13: =$F$9 -> 1 | F13: =$G$9 -> Cube | H13: =SUM(H11:H12) -> 2357.5
D14: Rate for 1 | E14: =$G$9 -> Cube | H14: =H13/F9 -> 2357.5
D15: Rate(Say) | G15: 1Cube | H15: =H14 -> 2357.5
D16: Rate(Say) | G16: 1 ft3 | H16: =H15/100 -> 23.575
D17: Rate(Say) | G17: 1m3 | H17: =ROUND(H15/2.83,0) -> 833
A19: 02.A.02 | C19: Backfilling to trenches with Imported Material
E20: Analysis for | F20: 1 | G20: Cube
B21: No | C21: Item Description | D21: Item Ref | E21: Unit | F21: Quantity | G21: Rate | H21: Amount
B22: 1 | C22: Earth Delivered at Site | D22: M-042 | E22: Cube | F22: 1 | G22: ='Basic Rates'!E45 -> 5000 | H22: =F22*G22 -> 5000
B23: 1.01 | C23: Allow 15% of Items ( 1 ) for Compacting | H23: =H22*0.15 -> 750
B24: 1.02 | C24: U / SK Labourer | D24: L-007 | E24: Day | F24: 1.25 | G24: ='Basic Rates'!J10 -> 2300 | H24: =F24*G24 -> 2875
D25: Total for | E25: =$F$20 -> 1 | F25: =$G$20 -> Cube | H25: =SUM(H22:H24) -> 8625
D26: Rate for 1 | E26: =$G$20 -> Cube | H26: =H25/F20 -> 8625
D27: Rate(Say) | G27: 1Cube | H27: =H26 -> 8625
D28: Rate(Say) | G28: 1 ft3 | H28: =H27/100 -> 86.25
D29: Rate(Say) | G29: 1m3 | H29: =ROUND(H27/2.83,0) -> 3048
A31: 02.A.03 | C31: Filling under floors including levelling, watering & compacting in 3" layers with available and selected earth at site
E32: Analysis for | F32: 1 | G32: Cube
B33: No | C33: Item Description | D33: Item Ref | E33: Unit | F33: Quantity | G33: Rate | H33: Amount
B34: 1.02 | C34: U / SK Labourer | D34: L-007 | E34: Day | F34: 2 | G34: ='Basic Rates'!J10 -> 2300 | H34: =F34*G34 -> 4600
B35: 1.02 | C35: Allow 2.5% of Items ( 1 ) for Tools | H35: =H34*2.5/100 -> 115
D36: Total for | E36: =$F$32 -> 1 | F36: =$G$32 -> Cube | H36: =SUM(H34:H35) -> 4715
D37: Rate for 1 | E37: =$G$32 -> Cube | H37: =H36/F32 -> 4715
D38: Rate(Say) | G38: 1Cube | H38: =H37 -> 4715
D39: Rate(Say) | G39: 1 ft3 | H39: =H38/100 -> 47.15
D40: Rate(Say) | G40: 1m3 | H40: =ROUND(H38/2.83,0) -> 1666
A42: 02.A.04 | C42: Filling under floors including levelling, watering & compacting in 3" layers with imported selected earth
E43: Analysis for | F43: 1 | G43: Cube
B44: No | C44: Item Description | D44: Item Ref | E44: Unit | F44: Quantity | G44: Rate | H44: Amount
B45: 1.02 | C45: Earth Delivered at Site | D45: M-042 | E45: Cu | F45: 1 | G45: ='Basic Rates'!E45 -> 5000 | H45: =F45*G45 -> 5000
B46: 1.03 | C46: Allow 15% of Items ( 1.02 ) for Compaction | H46: =H45*0.15 -> 750
...

Sheet 03
A2: 03. Anti termite Treatment & DPC
B4: A. | C4: Anti Termite Treatment
B5: B. | C5: DPC
A7: Anti Termite Treatment
A8: 03.A.01 | C8: Anti-Termite treatment on excavated foundation and compacted soil under floors.
E9: Analysis for | F9: 1 | G9: Sqr
B10: No | C10: Item Description | D10: Item Ref | E10: Unit | F10: Quantity | G10: Rate | H10: Amount
B11: 1 | C11: D. D. T. Powder | D11: M-038 | E11: Lbs | F11: 16 | G11: ='Basic Rates'!E41 -> 25 | H11: =F11*G11 -> 400
B12: 1.01 | C12: Water | D12: M-157 | E12: Gal | F12: 20 | G12: ='Basic Rates'!E161 -> 0.3 | H12: =F12*G12 -> 6
B13: 1.02 | C13: U / SK Labourer | D13: L-007 | E13: Day | F13: 0.5 | G13: ='Basic Rates'!J10 -> 2300 | H13: =F13*G13 -> 1150
D14: Total for | E14: =$F$9 -> 1 | F14: =$G$9 -> Sqr | H14: =SUM(H11:H13) -> 1556
D15: Rate for 1 | E15: =$G$9 -> Sqr | H15: =H14/F9 -> 1556
D16: Rate(Say) | G16: 1Sqr | H16: =H15 -> 1556
D17: Rate(Say) | G17: 1ft2 | H17: =H16/100 -> 15.56
D18: Rate(Say) | G18: 1m2 | H18: =H17*10.76 -> 167.4256
A21: DPC
A23: 03.B.01 | C23: 3/4" thick DPC in cement sand 1:2 finished with 2 coats hot tar and blinded with sand.
E24: Analysis for | F24: 1 | G24: Sqr
B25: No | C25: Item Description | D25: Item Ref | E25: Unit | F25: Quantity | G25: Rate | H25: Amount
B26: 1.01 | C26: Cement | D26: M-026 | E26: Bag | F26: 2.25 | G26: ='Basic Rates'!E29 -> 2400 | H26: =G26*F26 -> 5400
B27: 1.02 | C27: Sand | D27: M-113 | E27: Cube | F27: 0.11 | G27: ='Basic Rates'!E116 -> 18000 | H27: =G27*F27 -> 1980
B28: 1.03 | C28: Bitumen | D28: M-006 | E28: Gal | F28: 1.5 | G28: ='Basic Rates'!E9 -> 80 | H28: =G28*F28 -> 120
B29: 1.04 | C29: Fire Wood | D29: M-046 | E29: Lbs | F29: 10 | G29: ='Basic Rates'!E49 -> 250 | H29: =G29*F29 -> 2500
B30: 1.05 | C30: Water | D30: M-157 | E30: Gal | F30: 10 | G30: ='Basic Rates'!E161 -> 0.3 | H30: =G30*F30 -> 3
B31: 1.0599999 | C31: Mason | D31: L-009 | E31: Day | F31: 1.25 | G31: ='Basic Rates'!J6 -> 3500 | H31: =G31*F31 -> 4375
B32: 1.0700001 | C32: U / SK Labourer | D32: L-007 | E32: Day | F32: 2.5 | G32: ='Basic Rates'!J10 -> 2300 | H32: =G32*F32 -> 5750
D33: Total for | E33: =F24 -> 1 | F33: =$G$24 -> Sqr | H33: =SUM(H26:H32) -> 20128
D34: Rate for 1 | E34: =$G$24 -> Sqr | H34: =H33/F24 -> 20128
D35: Rate(Say) | G35: 1Sqr | H35: =ROUND(H34,0) -> 20128
D36: Rate(Say) | G36: 1ft2 | H36: =H35/100 -> 201.28
D37: Rate(Say) | G37: 1m2 | H37: =H36*10.76 -> 2165.7728

Sheet 04
A2: 04. Random Rubble Masonry Work
A4: 04.01 | C4: Random Rubble Masonry in cement mortar 1:5 in foundation
E5: Analysis for | F5: 1 | G5: Cube
B6: No | C6: Item Description | D6: Item Ref | E6: Unit | F6: Quantity | G6: Rate | H6: Amount
B7: 1.01 | C7: 6" - 9" Rubble | D7: M-111 | E7: Cube | F7: 1.3 | G7: ='Basic Rates'!E114 -> 9000 | H7: =G7*F7 -> 11700
B8: =B7+0.01 -> 1.02 | C8: Cement | D8: M-026 | E8: Bag | F8: 5 | G8: ='Basic Rates'!E29 -> 2400 | H8: =G8*F8 -> 12000
B9: =B8+0.01 -> 1.03 | C9: Sand | D9: M-113 | E9: Cube | F9: 0.3 | G9: ='Basic Rates'!E116 -> 18000 | H9: =G9*F9 -> 5400
B10: =B9+0.01 -> 1.04 | C10: Water | D10: M-157 | E10: Gal | F10: 100 | G10: ='Basic Rates'!E161 -> 0.3 | H10: =G10*F10 -> 30
B11: =B10+0.01 -> 1.05 | C11: Mason | D11: L-009 | E11: Day | F11: 4 | G11: ='Basic Rates'!J6 -> 3500 | H11: =G11*F11 -> 14000
B12: =B11+0.01 -> 1.06 | C12: U / SK Labourer | D12: L-007 | E12: Day | F12: 6 | G12: ='Basic Rates'!J10 -> 2300 | H12: =G12*F12 -> 13800
D13: Total for | E13: =$F$5 -> 1 | F13: =$G$5 -> Cube | H13: =SUM(H7:H12) -> 56930
D14: Rate for 1 | E14: =$G$5 -> Cube | H14: =H13/F5 -> 56930
D15: Rate(Say) | G15: 1Cube | H15: =ROUND(H14,0) -> 56930
D16: Rate(Say) | G16: 1ft3 | H16: =H15/100 -> 569.3
D17: Rate(Say) | G17: 1m3 | H17: =H15/2.83 -> 20116.608
A19: 04.02 | C19: Random Rubble Masonry in cement mortar 1:5 in Superstructure
E20: Analysis for | F20: 1 | G20: Cube
B21: No | C21: Item Description | D21: Item Ref | E21: Unit | F21: Quantity | G21: Rate | H21: Amount
B22: 1.01 | C22: 6" - 9" Rubble | D22: M-111 | E22: Cu | F22: 1.3 | G22: ='Basic Rates'!E114 -> 9000 | H22: =G22*F22 -> 11700
B23: =B22+0.01 -> 1.02 | C23: Cement | D23: M-026 | E23: Bag | F23: 5 | G23: ='Basic Rates'!E29 -> 2400 | H23: =G23*F23 -> 12000
B24: =B23+0.01 -> 1.03 | C24: Sand | D24: M-113 | E24: Cu | F24: 0.3 | G24: ='Basic Rates'!E116 -> 18000 | H24: =G24*F24 -> 5400
B25: =B24+0.01 -> 1.04 | C25: Water | D25: M-157 | E25: Gal | F25: 100 | G25: ='Basic Rates'!E161 -> 0.3 | H25: =G25*F25 -> 30
B26: =B25+0.01 -> 1.05 | C26: Mason | D26: L-009 | E26: Day | F26: 4.5 | G26: ='Basic Rates'!J6 -> 3500 | H26: =G26*F26 -> 15750
B27: =B26+0.01 -> 1.06 | C27: U / SK Labourer | D27: L-007 | E27: Day | F27: 7 | G27: ='Basic Rates'!J10 -> 2300 | H27: =G27*F27 -> 16100
B28: =B27+0.01 -> 1.07 | C28: Allow 3% of Items ( 1.05, 1.06 ) for Scaffolding | D28: - | E28: - | F28: - | G28: - | H28: =(H26+H27)*3/100 -> 955.5
D29: Total for | E29: =$F$20 -> 1 | F29: =$G$20 -> Cube | H29: =SUM(H22:H28) -> 61935.5
D30: Rate for 1 | E30: =$G$20 -> Cube | H30: =H29/F20 -> 61935.5
D31: Rate(Say) | G31: 1Cube | H31: =ROUND(H30,0) -> 61936
D32: Rate(Say) | G32: 1ft3 | H32: =H31/100 -> 619.36
D33: Rate(Say) | G33: 1m3 | H33: =H31/2.83 -> 21885.512

Sheet 05
A2: 05. Concrete Work
B4: A. | C4: Mixing Concrete
B5: B. | C5: Screed
B6: C. | C6: Mass Concrete
B7: D. | C7: Column
B8: E. | C8: Beam
B9: F. | C9: Slab
B10: G. | C10: Lintol
D12: Mixing Concrete
A14: 05.A.01 | C14: Mixing Concrete 1:1-1/2:3(3/4")
E15: Analysis for | F15: 1 | G15: Cube
B16: No. | C16: Item Description | D16: Item Ref | E16: Unit | F16: Quantity | G16: Rate | H16: Amount
B17: 1.01 | C17: Cement | D17: M-026 | E17: Bag | F17: 23 | G17: ='Basic Rates'!E29 -> 2400 | H17: =G17*F17 -> 55200
B18: 1.02 | C18: Sand | D18: M-113 | E18: Cube | F18: 0.42 | G18: ='Basic Rates'!E116 -> 18000 | H18: =G18*F18 -> 7560
B19: 1.03 | C19: 3/4 " Metal | D19: M-066 | E19: Cube | F19: 0.82 | G19: ='Basic Rates'!E69 -> 15000 | H19: =G19*F19 -> 12300
B20: 1.04 | C20: Hire of Mixer | D20: P-001 | E20: Day | F20: 0.333 | G20: ='Basic Rates'!O4 -> 5000 | H20: =G20*F20 -> 1665
B21: 1.05 | C21: Water | D21: M-157 | E21: Gal | F21: 150 | G21: ='Basic Rates'!E161 -> 0.3 | H21: =G21*F21 -> 45
B22: 1.0599999 | C22: SK Labour | D22: L-003 | E22: Day | F22: 0.333 | G22: ='Basic Rates'!J6 -> 3500 | H22: =G22*F22 -> 1165.5
B23: 1.0700001 | C23: U / SK Labourer | D23: L-007 | E23: Day | F23: 2 | G23: ='Basic Rates'!J10 -> 2300 | H23: =G23*F23 -> 4600
D24: Total for | E24: =$F$15 -> 1 | F24: =$G$15 -> Cube | H24: =SUM(H17:H23) -> 82535.5
D25: Rate for 1 | E25: =$G$15 -> Cube | H25: =H24/F15 -> 82535.5
D26: Rate(Say) | G26: 1Cube | H26: =ROUND(H25,-1) -> 82540
D27: Rate(Say) | G27: 1m3 | H27: =H26/2.83 -> 29166.078
A29: 05.A.02 | C29: Mixing Concrete 1:3:6(1 1/2")
E30: Analysis for | F30: 1 | G30: Cube
B31: No | C31: Item Description | D31: Item Ref | E31: Unit | F31: Quantity | G31: Rate | H31: Amount
B32: 1.01 | C32: Cement | D32: M-026 | E32: Bag | F32: 13 | G32: ='Basic Rates'!E29 -> 2400 | H32: =G32*F32 -> 31200
B33: 1.02 | C33: Sand | D33: M-113 | E33: Cube | F33: 0.53 | G33: ='Basic Rates'!E116 -> 18000 | H33: =G33*F33 -> 9540
B34: 1.03 | C34: 1 1/2 " Metal | D34: M-065 | E34: Cube | F34: 0.92 | G34: ='Basic Rates'!E68 -> 9000 | H34: =G34*F34 -> 8280
B35: 1.04 | C35: Hire of Mixer | D35: P-001 | E35: Day | F35: 0.333 | G35: ='Basic Rates'!O4 -> 5000 | H35: =G35*F35 -> 1665
B36: 1.05 | C36: Water | D36: M-157 | E36: Gal | F36: 110 | G36: ='Basic Rates'!E161 -> 0.3 | H36: =G36*F36 -> 33
B37: 1.0599999 | C37: SK Labour | D37: L-003 | E37: Day | F37: 0.333 | G37: ='Basic Rates'!J6 -> 3500 | H37: =G37*F37 -> 1165.5
B38: 1.0700001 | C38: U / SK Labourer | D38: L-007 | E38: Day | F38: 2 | G38: ='Basic Rates'!J10 -> 2300 | H38: =G38*F38 -> 4600
D39: Total for | E39: =$F$30 -> 1 | F39: =$G$30 -> Cube | H39: =SUM(H32:H38) -> 56483.5
D40: Rate for 1 | E40: =$G$30 -> Cube | H40: =H39/F30 -> 56483.5
D41: Rate(Say) | G41: 1Cube | H41: =ROUND(H40,-1) -> 56480
D42: Rate(Say) | G42: 1m3 | H42: =H41/2.83 -> 19957.597
A44: 05.A.03 | C44: Mixing Concrete 1:2 1/2 :5 (1")
E45: Analysis for | F45: 1 | G45: Cube
B46: No | C46: Item Description | D46: Item Ref | E46: Unit | F46: Quantity | G46: Rate | H46: Amount
...

Sheet 06
A2: 06. Formwork
B4: A. | C4: Column
B5: B. | C5: Beam
B6: C. | C6: Slab
D8: Column
A10: 06.A.01 | C10: Sawn timber formwork to 9" x 9" cement concrete column in ground floor.
E11: Analysis for | F11: 0.15 | G11: Sq
B12: No | C12: Item Description | D12: Item Ref | E12: Unit | F12: Quantity | G12: Rate | H12: Amount
B13: 1.01 | C13: Sawn timber formwork to 9" x 9" cement concrete column in ground floor - Making Mould | D13: 06.A.02 | E13: 1 Use | F13: 1 | G13: =H42 -> 1181 | H13: =G13*F13 -> 1181
B14: 1.02 | C14: Bolts 16mm 18" (12 nos 20 uses) | D14: M-010 | E14: No | F14: =12/20 -> 0.6 | G14: ='Basic Rates'!E13 -> 75 | H14: =G14*F14 -> 45
B15: 1.03 | C15: Mould Oil | D15: M-071 | E15: litre | F15: 0.5 | G15: ='Basic Rates'!E74 -> 35 | H15: =G15*F15 -> 17.5
B16: 1.04 | C16: Timber props 4" x 2" | D16: M-144 | E16: L.ft | F16: =35/10 -> 3.5 | G16: ='Basic Rates'!E148 -> 65 | H16: =G16*F16 -> 227.5
B17: 1.05 | C17: Carpenter - assembling | D17: L-008 | E17: Day | F17: 0.25 | G17: ='Basic Rates'!J11 -> 3500 | H17: =G17*F17 -> 875
B18: 1.0599999 | C18: U / SK Labourer - assembling | D18: L-007 | E18: Day | F18: 0.25 | G18: ='Basic Rates'!J10 -> 2300 | H18: =G18*F18 -> 575
B19: 1.0700001 | C19: Carpenter - dismantling, cleaning & repairing | D19: L-008 | E19: Day | F19: 0.25 | G19: ='Basic Rates'!J11 -> 3500 | H19: =G19*F19 -> 875
B20: 1.08 | C20: U / SK Labourer - dismantling, cleaning & repairing | D20: L-007 | E20: Day | F20: 0.25 | G20: ='Basic Rates'!J10 -> 2300 | H20: =G20*F20 -> 575 | L20: =0.25+0.5 -> 0.75
D21: Total for | E21: =$F$11 -> 0.15 | F21: =$G$11 -> Sq | H21: =SUM(H13:H20) -> 4371
D22: Rate for 1 | E22: =$G$11 -> Sq | H22: =H21/F11 -> 29140 | L22: =1100000 -> 1100000
D23: Rate(Say) | G23: 1Sq | H23: =ROUND(H22,0) -> 29140 | L23: =L22*18/100 -> 198000
D24: Rate(Say) | G24: 1ft2 | H24: =H23/100 -> 291.4 | L24: =L23/12 -> 16500
D25: Rate(Say) | G25: 1m2 | H25: =H24*10.76 -> 3135.464 | L25: =L24*4 -> 66000
D26: Ground floor - First Floor | G26: 1m2 | H26: =H25 -> 3135.464
D27: First Floor - Second Floor | G27: 1m2 | H27: =H26*1.1 -> 3449.0104
D28: Second Floor - Third Floor | G28: 1m2 | H28: =H27*1.1 -> 3793.9114
D29: Third Floor - Fourth Floor | G29: 1m2 | H29: =H28*1.1 -> 4173.3026
A31: 06.A.02 | C31: Sawn timber formwork to 9" x 9" cement concrete column in ground floor - Making Mould
E32: Analysis for | F32: 4 | G32: Uses
B33: No | C33: Item Description | D33: Item Ref | E33: Unit | F33: Quantity | G33: Rate | H33: Amount
B34: 1.01 | C34: 1" Thick Class II Timber | D34: M-141 | E34: Sq.ft | F34: 18.15 | G34: ='Basic Rates'!E145 -> 65 | H34: =G34*F34 -> 1179.75
B35: 1.02 | C35: 2" x 2" Class II Timber In Yokes | D35: M-143 | E35: L.ft | F35: 17.1 | G35: ='Basic Rates'!E147 -> 22 | H35: =G35*F35 -> 376.2
B36: 1.03 | C36: 2" x 1" Class II Timber Battens. | D36: M-142 | E36: L.ft | F36: 16.12 | G36: ='Basic Rates'!E146 -> 12 | H36: =G36*F36 -> 193.44
B37: 1.04 | C37: Wire Nails | D37: M-161 | E37: Lbs | F37: 1.5 | G37: ='Basic Rates'!E165 -> 50 | H37: =G37*F37 -> 75
B38: 1.05 | C38: Carpenter | D38: L-008 | E38: Day | F38: 0.5 | G38: ='Basic Rates'!J11 -> 3500 | H38: =G38*F38 -> 1750
B39: 1.0599999 | C39: U / SK Labourer | D39: L-007 | E39: Day | F39: 0.5 | G39: ='Basic Rates'!J10 -> 2300 | H39: =G39*F39 -> 1150
D40: Total for | E40: =$F$32 -> 4 | F40: =$G$32 -> Uses | H40: =SUM(H34:H39) -> 4724.39
D41: Rate for 1 | E41: =$G$32 -> Uses | H41: =H40/F32 -> 1181.0975
D42: Rate(Say) | G42: 1 Use | H42: =ROUND(H41,0) -> 1181
D44: Beam
A46: 06.B.01 | C46: Sawn timber formwork for concrete beams in ground floor
E47: Analysis for | F47: 0.55 | G47: Sq
...

Sheet 07
A2: 07. Reinforcement
A4: 7.01 | C4: Tor steel reinforcement to lintels, slabs, beams or columns bent to shape, laid in position and tied with G.I. Wire as directed.
E5: Analysis for | F5: 1 | G5: Cwt.
B6: No | C6: Item Description | D6: Item Ref | E6: Unit | F6: Quantity | G6: Rate | H6: Amount
B7: 1.01 | C7: M.S./Tor Steel Rods including transport to site | D7: M-152 | E7: kg | F7: 50 | G7: ='Basic Rates'!E156 -> 68 | H7: =G7*F7 -> 3400
B8: 1.02 | C8: Allow 15% of Items ( 1.01 ) for Wastage | D8: - | E8: - | F8: - | G8: - | H8: =H7*15/100 -> 510
B9: 1.03 | C9: 16 BWG Binding Wire | D9: M-005 | E9: Lbs | F9: 1.5 | G9: ='Basic Rates'!E8 -> 560 | H9: =G9*F9 -> 840
B10: 1.04 | C10: Allow 1.5% of Items ( 1.01 ) for spaces or chairs | D10: - | E10: - | F10: - | G10: - | H10: =H7*0.015 -> 51
B11: 1.05 | C11: SK Labour | D11: L-003 | E11: Day | F11: 1 | G11: ='Basic Rates'!J6 -> 3500 | H11: =G11*F11 -> 3500
B12: 1.0599999 | C12: U / SK Labourer | D12: L-007 | E12: Day | F12: 1 | G12: ='Basic Rates'!J10 -> 2300 | H12: =G12*F12 -> 2300
D13: Total for | E13: =$F$5 -> 1 | F13: =$G$5 -> Cwt. | H13: =SUM(H7:H12) -> 10601
D14: Rate for 1 | E14: =$G$5 -> Cwt. | H14: =H13/F5 -> 10601
D15: Rate(Say) | G15: 1Cwt | H15: =ROUND(H14,0) -> 10601
D16: Rate(Say) | G16: 1Kg | H16: =H15/50 -> 212.02
A19: 7.02 | C19: Mild Steel reinforcement to lintels, slabs, beams or columns bent to shape, laid in position and tied with G.I. Wire as directed.
E20: Analysis for | F20: 1 | G20: Cwt.
B21: No | C21: Item Description | D21: Item Ref | E21: Unit | F21: Quantity | G21: Rate | H21: Amount
B22: 1.01 | C22: M.S./Tor Steel Rods including transport to site | D22: M-068 | E22: kg | F22: 50 | G22: ='Basic Rates'!E71 -> 68 | H22: =G22*F22 -> 3400
B23: 1.02 | C23: Allow 15% of Items ( 1.01 ) for Wastage | D23: - | E23: - | F23: - | G23: - | H23: =H22*15/100 -> 510
B24: 1.03 | C24: 16 BWG Binding Wire | D24: M-005 | E24: Lbs | F24: 1.5 | G24: ='Basic Rates'!$E$8 -> 560 | H24: =G24*F24 -> 840
B25: 1.04 | C25: SK Labour | D25: L-003 | E25: Day | F25: 1 | G25: ='Basic Rates'!$J$6 -> 3500 | H25: =G25*F25 -> 3500
B26: 1.05 | C26: U / SK Labourer | D26: L-007 | E26: Day | F26: 1 | G26: ='Basic Rates'!$J$10 -> 2300 | H26: =G26*F26 -> 2300
D27: Total for | E27: =$F$5 -> 1 | F27: =$G$5 -> Cwt. | H27: =SUM(H22:H26) -> 10550
D28: Rate for 1 | E28: =$G$5 -> Cwt. | H28: =H27/F20 -> 10550
D29: Rate(Say) | G29: 1Cwt | H29: =ROUND(H28,0) -> 10550
D30: Rate(Say) | G30: 1Kg | H30: =H29/50 -> 211

Sheet 08
A2: 08. Block Work
A4: 08.01 | C4: 8" Thick hollow block work in cement and sand mortar 1:5 in ground floor (Cavities unfilled)
E5: Analysis for | F5: 1 | G5: Sqr
B6: No | C6: Item Description | D6: Item Ref | E6: Unit | F6: Quantity | G6: Rate | H6: Amount
B7: 1.01 | C7: Hollow Cement Block (16"x 8"x 8") | D7: M-057 | E7: No | F7: 112 | G7: ='Basic Rates'!E60 -> 180 | H7: =G7*F7 -> 20160
B8: 1.02 | C8: Allow 5% of Items ( 1.01 ) for Wastage | D8: - | E8: - | F8: - | G8: - | H8: =H7*5/100 -> 1008
B9: 1.03 | C9: Cement | D9: M-026 | E9: Bag | F9: 0.75 | G9: ='Basic Rates'!E29 -> 2400 | H9: =G9*F9 -> 1800
B10: 1.04 | C10: Sand | D10: M-113 | E10: Cube | F10: 0.06 | G10: ='Basic Rates'!E116 -> 18000 | H10: =G10*F10 -> 1080
B11: 1.05 | C11: Mason | D11: L-009 | E11: Day | F11: 1.5 | G11: ='Basic Rates'!J12 -> 3500 | H11: =G11*F11 -> 5250
B12: 1.0599999 | C12: U / SK Labourer | D12: L-007 | E12: Day | F12: 2.5 | G12: ='Basic Rates'!J10 -> 2300 | H12: =G12*F12 -> 5750
B13: 1.0700001 | C13: Allow 3% of Items ( 1.05, 1.06 ) for Scaffolding | D13: - | E13: - | F13: - | G13: - | H13: =(H11+H12)*3/100 -> 330
D14: Total for | E14: =$F$5 -> 1 | F14: =$G$5 -> Sqr | H14: =SUM(H7:H13) -> 35378
D15: Rate for 1 | E15: =$G$5 -> Sqr | H15: =H14/F5 -> 35378
D16: Rate(Say) | G16: 1 Sq | H16: =ROUND(H15,0) -> 35378
D17: Rate(Say) | G17: 1ft2 | H17: =H16/100 -> 353.78
D18: Rate(Say) | G18: 1m2 | H18: =H17*10.76 -> 3806.6728
D19: Ground floor | G19: 1m2 | H19: =H18 -> 3806.6728
D20: First Floor | G20: 1m2 | H20: =H19*1.1 -> 4187.3401
D21: Second Floor | G21: 1m2 | H21: =H20*1.1 -> 4606.0741
D22: 3rd floor | G22: 1m2 | H22: =H21*1.1 -> 5066.6815
A24: 08.02 | C24: 6" Thick hollow block work in cement and sand mortar 1:5 with cavities unfilled.
E25: Analysis for | F25: 1 | G25: Sqr
B26: No | C26: Item Description | D26: Item Ref | E26: Unit | F26: Quantity | G26: Rate | H26: Amount
B27: 1.01 | C27: Hollow Cement Blocks (16"x 8"x 6") | D27: M-059 | E27: No | F27: 112 | G27: ='Basic Rates'!E62 -> 160 | H27: =G27*F27 -> 17920
B28: 1.02 | C28: Allow 5% of Items ( 1.01 ) for Wastage | D28: - | E28: - | F28: - | G28: - | H28: =H27*5/100 -> 896
B29: 1.03 | C29: Cement | D29: M-026 | E29: Bag | F29: 0.65 | G29: ='Basic Rates'!E29 -> 2400 | H29: =G29*F29 -> 1560
B30: 1.04 | C30: Sand | D30: M-113 | E30: Cube | F30: 0.07 | G30: ='Basic Rates'!E116 -> 18000 | H30: 51
B31: 1.05 | C31: Mason | D31: L-009 | E31: Day | F31: 1.5 | G31: ='Basic Rates'!J12 -> 3500 | H31: =G31*F31 -> 5250
B32: 1.0599999 | C32: U / SK Labourer | D32: L-007 | E32: Day | F32: 2 | G32: ='Basic Rates'!J10 -> 2300 | H32: =G32*F32 -> 4600
B33: 1.0700001 | C33: Allow 3% of Items ( 1.05, 1.06 ) for Scaffolding | D33: - | E33: - | F33: - | G33: - | H33: =(H31+H32)*3/100 -> 295.5
D34: Total for | E34: =$F$25 -> 1 | F34: =$G$25 -> Sqr | H34: =SUM(H27:H33) -> 30572.5
D35: Rate for 1 | E35: =$G$25 -> Sqr | H35: =H34/F25 -> 30572.5
D36: Rate(Say) | G36: 1 Sq | H36: =H35 -> 30572.5
D37: Rate(Say) | G37: 1ft2 | H37: =H36/100 -> 305.725
D38: Rate(Say) | G38: 1m2 | H38: =H37*10.76 -> 3289.601
D39: Ground floor | G39: 1m2 | H39: =H38 -> 3289.601
D40: First Floor | G40: 1m2 | H40: =H39*1.1 -> 3618.5611
D41: Second Floor | G41: 1m2 | H41: =H40*1.1 -> 3980.4172
D42: Third Floor | G42: 1m2 | H42: =H41*1.1 -> 4378.4589
A45: 08.03 | C45: 4" Thick hollow block work in cement and sand mortar 1:5 with cavities unfilled.
...

Sheet 09
A2: 09. Brick Work
A4: 09.01 | C4: Brick Work in cement sand 1:5 in 4-1/2" thick walls in ground floor
E5: Analysis for | F5: 1 | G5: Sqr
B6: No | C6: Item Description | D6: Item Ref | E6: Unit | F6: Quantity | G6: Rate | H6: Amount
B7: 1.01 | C7: Bricks | D7: M-019 | E7: No | F7: 550 | G7: ='Basic Rates'!E22 -> 20 | H7: =G7*F7 -> 11000
B8: 1.02 | C8: Allow 5% of Items ( 1.01 ) for Wastage | D8: - | E8: - | F8: - | G8: - | H8: =H7*5/100 -> 550
B9: 1.03 | C9: Cement | D9: M-026 | E9: Bag | F9: 1.3 | G9: ='Basic Rates'!E29 -> 2400 | H9: =G9*F9 -> 3120
B10: 1.04 | C10: Sand | D10: M-113 | E10: Cu | F10: 0.1 | G10: ='Basic Rates'!E116 -> 18000 | H10: =G10*F10 -> 1800
B11: 1.05 | C11: Water | D11: M-157 | E11: Gal | F11: 50 | G11: ='Basic Rates'!E161 -> 0.3 | H11: =G11*F11 -> 15
B12: 1.06 | C12: Mason | D12: L-009 | E12: Day | F12: 1.5 | G12: ='Basic Rates'!J12 -> 3500 | H12: =G12*F12 -> 5250
B13: 1.07 | C13: U / SK Labourer | D13: L-007 | E13: Day | F13: 2 | G13: ='Basic Rates'!J10 -> 2300 | H13: =G13*F13 -> 4600
B14: 1.08 | C14: Allow 5% of Items (1.06, 1.07 ) for Scaffolding | D14: - | E14: - | F14: - | G14: - | H14: =(H12+H13)*5/100 -> 492.5
D15: Total for | E15: =$F$5 -> 1 | F15: =$G$5 -> Sqr | H15: =SUM(H7:H14) -> 26827.5
D16: Rate for 1 | E16: =$G$5 -> Sqr | H16: =H15/F5 -> 26827.5
D17: Rate(Say) | G17: 1 Sq | H17: =ROUND(H16,0) -> 26828
D18: Rate(Say) | G18: 1ft2 | H18: =H17/100 -> 268.28
D19: Rate(Say) | G19: 1m2 | H19: =H18*10.76 -> 2886.6928
D20: Ground floor | G20: 1m2 | H20: =H19 -> 2886.6928
D21: First Floor | G21: 1m2 | H21: =H20*1.05 -> 3031.0274
D22: Second Floor | G22: 1m2 | H22: =H21*1.05 -> 3182.5788
D23: Third Floor | G23: 1m2 | H23: =H22*1.05 -> 3341.7078
A25: 09.02 | C25: 9" thick brick wall cement sand 1:5 in ground floor
E26: Analysis for | F26: 1 | G26: Sqr
B27: No | C27: Item Description | D27: Item Ref | E27: Unit | F27: Quantity | G27: Rate | H27: Amount
B28: 1.01 | C28: Bricks | D28: M-019 | E28: No | F28: 1090 | G28: ='Basic Rates'!E22 -> 20 | H28: =G28*F28 -> 21800
B29: 1.02 | C29: Allow 5% of Items ( 1.01 ) for Wastage | D29: - | E29: - | F29: - | G29: - | H29: =H28*5/100 -> 1090
B30: 1.03 | C30: Cement | D30: M-026 | E30: Bag | F30: 3 | G30: ='Basic Rates'!E29 -> 2400 | H30: =G30*F30 -> 7200
B31: 1.04 | C31: Sand | D31: M-113 | E31: Cu | F31: 0.2 | G31: ='Basic Rates'!E116 -> 18000 | H31: =G31*F31 -> 3600
B32: 1.05 | C32: Water | D32: M-157 | E32: Gal | F32: 115 | G32: ='Basic Rates'!E161 -> 0.3 | H32: =G32*F32 -> 34.5
B33: 1.06 | C33: Mason | D33: L-009 | E33: Day | F33: 2.25 | G33: ='Basic Rates'!J12 -> 3500 | H33: =G33*F33 -> 7875
B34: 1.07 | C34: U / SK Labour | D34: L-007 | E34: Day | F34: 3.75 | G34: ='Basic Rates'!J10 -> 2300 | H34: =G34*F34 -> 8625
B35: 1.08 | C35: Allow 3% of Items (1.06, 1.07 ) for Scaffolding | D35: - | E35: - | F35: - | G35: - | H35: =(H33+H34)*3/100 -> 495
D36: Total for | E36: =$F$26 -> 1 | F36: =$G$26 -> Sqr | H36: =SUM(H28:H35) -> 50719.5
D37: Rate for 1 | E37: =$G$26 -> Sqr | H37: =H36/F26 -> 50719.5
D38: Rate(Say) | G38: 1 Sq | H38: =ROUND(H37,0) -> 50720
D39: Rate(Say) | G39: 1ft2 | H39: =H38/100 -> 507.2
D40: Rate(Say) | G40: 1m2 | H40: =H39*10.76 -> 5457.472
D41: Ground floor | G41: 1m2 | H41: =H40 -> 5457.472
D42: First Floor | G42: 1m2 | H42: =H41*1.05 -> 5730.3456
D43: Second Floor | G43: 1m2 | H43: =H42*1.05 -> 6016.8629
...

Sheet 10
A2: 10. Roof Covering and Ceiling
B4: A. | C4: Roof Frame & Roof Covering
B5: B. | C5: Roof Plumbing
A7: Roof frame & Roof Covering
A9: 10.A.01 | C9: Timber framework for culicut pattern tile hip roof in single storey building consisting of wall plate , beam, ridge plate, rafters etc.(Preservative treatment to be measured separately)
E10: Analysis for | F10: 6 | G10: Sqrs
B11: No | C11: Item Description | D11: Item Ref | E11: Unit | F11: Quantity | G11: Rate | H11: Amount
B12: 1.01 | C12: Timber Class I | D12: M-136 | E12: Cu.ft | F12: 34 | G12: ='Basic Rates'!$E$139 -> 1200 | H12: =G12*F12 -> 40800
B13: 1.02 | C13: Allow 10% of Items ( 1.01 ) for Wastage | D13: - | E13: - | F13: - | G13: - | H13: =(H12)*10/100 -> 4080
B14: 1.03 | C14: 2"X1" Reepers | D14: M-149 | E14: L.ft | F14: 660 | G14: ='Basic Rates'!$E$153 -> 12 | H14: =G14*F14 -> 7920
B15: 1.04 | C15: Allow 5% of Items ( 1.03 ) for Wastage | D15: - | E15: - | F15: - | G15: - | H15: =(H14)*5/100 -> 396
B16: 1.05 | C16: Wire Nails 6" Long | D16: M-163 | E16: Lbs | F16: 8 | G16: ='Basic Rates'!E167 -> 25 | H16: =G16*F16 -> 200
B17: 1.0599999 | C17: Wire Nails 2" Long | D17: M-162 | E17: Lbs | F17: 2 | G17: ='Basic Rates'!E166 -> 25 | H17: =G17*F17 -> 50
B18: 1.0700001 | C18: Carpenter | D18: L-008 | E18: Day | F18: 7 | G18: ='Basic Rates'!$J$11 -> 3500 | H18: =G18*F18 -> 24500
B19: 1.08 | C19: U / SK Labourer | D19: L-007 | E19: Day | F19: 8 | G19: ='Basic Rates'!$J$10 -> 2300 | H19: =G19*F19 -> 18400
D20: Total for | E20: =$F$10 -> 6 | F20: =$G$10 -> Sqrs | H20: =SUM(H12:H19) -> 96346
D21: Rate for 1 | E21: =$G$10 -> Sqrs | H21: =H20/F10 -> 16057.667
D22: Rate(Say) | H22: =ROUND(H21,0) -> 16058
A24: 10.A.02 | C24: Roof Covering With calicut pattern clay tiles in single storeyed building
E25: Analysis for | F25: 6 | G25: Sqrs
B26: No | C26: Item Description | D26: Item Ref | E26: Unit | F26: Quantity | G26: Rate | H26: Amount
B27: 1.01 | C27: Tiles | D27: M-108 | E27: No | F27: 750 | G27: ='Basic Rates'!E111 -> 16 | H27: =G27*F27 -> 12000
B28: =B27+0.01 -> 1.02 | C28: Carpenter | D28: L-008 | E28: Day | F28: 3 | G28: ='Basic Rates'!$J$11 -> 3500 | H28: =G28*F28 -> 10500
B29: =B28+0.01 -> 1.03 | C29: U / SK Labourer | D29: L-007 | E29: Day | F29: 3 | G29: ='Basic Rates'!$J$10 -> 2300 | H29: =G29*F29 -> 6900
D30: Total for | E30: =$F$25 -> 6 | F30: =$G$25 -> Sqrs | H30: =SUM(H27:H29) -> 29400
D31: Rate for 1 | E31: =$G$25 -> Sqrs | H31: =H30/F25 -> 4900
D32: Rate(Say) | H32: =ROUND(H31,0) -> 4900
A34: 10.A.03 | C34: Timber framework for corrugated asbestos sheet roof in single storeyed building
E35: Analysis for | F35: 3.6 | G35: Sqrs
B36: No | C36: Item Description | D36: Item Ref | E36: Unit | F36: Quantity | G36: Rate | H36: Amount
B37: 1.01 | C37: Timber Class I | D37: M-136 | E37: Cu.ft | F37: 13.25 | G37: ='Basic Rates'!$E$139 -> 1200 | H37: =G37*F37 -> 15900
B38: 1.02 | C38: Allow 10% of Items ( 1.01 ) for Wastage | D38: - | E38: - | F38: - | G38: - | H38: =H37*10/100 -> 1590
B39: 1.03 | C39: Carpenter | D39: L-008 | E39: Day | F39: 2.5 | G39: ='Basic Rates'!$J$11 -> 3500 | H39: =G39*F39 -> 8750
B40: 1.04 | C40: U / SK Labourer | D40: L-007 | E40: Day | F40: 3 | G40: ='Basic Rates'!$J$10 -> 2300 | H40: =G40*F40 -> 6900
D41: Total for | E41: =$F$35 -> 3.6 | F41: =$G$35 -> Sqrs | H41: =SUM(H37:H40) -> 33140
D42: Rate for 1 | E42: =$G$35 -> Sqrs | H42: =H41/F35 -> 9205.5556
D43: Rate(Say) | H43: =ROUND(H42,0) -> 9206
A45: 10.A.04 | C45: Roof covering with corrugated asbestos sheets (Timber frame work and ridge covering measured separately)
E46: Analysis for | F46: 3.6 | G46: Sqrs
B47: No | C47: Item Description | D47: Item Ref | E47: Unit | F47: Quantity | G47: Rate | H47: Amount
...

Sheet 11
A2: 11. Doors & Windows
B4: A. | C4: Doors & Windows
B5: B. | C5: Ironmongery
A8: Doors & Windows
A10: 11.A.01 | C10: Door Single Hung 3' 3" X7' 0" high overall with frame having 1 1/4" thick sash and 3 1/4" X 2 1/4 ft. timber frame(glazing, ironmongery & painting measured separately)
E11: Analysis for | F11: 22.75 | G11: Sq.ft
B12: No | C12: Item Description | D12: Item Ref | E12: Unit | F12: Quantity | G12: Rate | H12: Amount
B13: 1.01 | C13: 4"X3" Timber | D13: M-138 | E13: Cu.ft | F13: 1.5 | G13: ='Basic Rates'!$E$141 -> 1300 | H13: =G13*F13 -> 1950
B14: 1.02 | C14: Spur Stone | D14: M-118 | E14: No | F14: 2 | G14: ='Basic Rates'!$E$121 -> 15 | H14: =G14*F14 -> 30
B15: 1.03 | C15: Fibre / Plastic Plugs | D15: M-045 | E15: No | F15: 6 | G15: ='Basic Rates'!$E$48 -> 1.5 | H15: =G15*F15 -> 9
B16: 1.04 | C16: 4" Long Brass Screws | D16: M-018 | E16: No | F16: 6 | G16: ='Basic Rates'!$E$21 -> 7.5 | H16: =G16*F16 -> 45
B17: 1.05 | C17: 5/8" Mild Steel Dowels 4" Long. | D17: M-067 | E17: No | F17: 2 | G17: ='Basic Rates'!$E$70 -> 6 | H17: =G17*F17 -> 12
B18: 1.0599999 | C18: 1 1/2" Planks | D18: M-139 | E18: Sq.ft | F18: 14 | G18: ='Basic Rates'!$E$142 -> 140 | H18: =G18*F18 -> 1960
B19: 1.0700001 | C19: 1" Planks | D19: M-139a | E19: Sq.ft | F19: 5 | G19: ='Basic Rates'!$E$143 -> 110 | H19: =G19*F19 -> 550
B20: 1.08 | C20: Carpenter | D20: L-008 | E20: Day | F20: 5 | G20: ='Basic Rates'!$J$11 -> 3500 | H20: =G20*F20 -> 17500
B21: 1.09 | C21: U / SK Labourer | D21: L-007 | E21: Day | F21: 1.5 | G21: ='Basic Rates'!$J$10 -> 2300 | H21: =G21*F21 -> 3450
D22: Total for | E22: =$F$11 -> 22.75 | F22: =$G$11 -> Sq.ft | H22: =SUM(H13:H21) -> 25506
D23: Rate for 1 | E23: =$G$11 -> Sq.ft | H23: =H22/F11 -> 1121.1429
D24: Rate(Say) | H24: =ROUND(H23,0) -> 1121
A26: 11.A.02 | C26: Door glazed and paneled double hung 4' 0" x 7' 0" high overall with frame including 1 1/4" thick sash and 3 1/4 x 2 1/4" frame (Glazing, Ironmongory and painting measured separately)
E27: Analysis for | F27: 28 | G27: Sq.ft
B28: No | C28: Item Description | D28: Item Ref | E28: Unit | F28: Quantity | G28: Rate | H28: Amount
B29: 1.01 | C29: 4"X3" Timber | D29: M-138 | E29: Cu.ft | F29: 1.66 | G29: ='Basic Rates'!$E$141 -> 1300 | H29: =G29*F29 -> 2158
B30: 1.02 | C30: Spur Stone | D30: M-118 | E30: No | F30: 2 | G30: ='Basic Rates'!$E$121 -> 15 | H30: =G30*F30 -> 30
B31: 1.03 | C31: Fibre / Plastic Plugs | D31: M-045 | E31: No | F31: 6 | G31: ='Basic Rates'!$E$48 -> 1.5 | H31: =G31*F31 -> 9
B32: 1.04 | C32: 4" Long Brass Screws | D32: M-018 | E32: No | F32: 6 | G32: ='Basic Rates'!$E$21 -> 7.5 | H32: =G32*F32 -> 45
B33: 1.05 | C33: 5/8" Mild Steel Dowels 4" Long. | D33: M-067 | E33: No | F33: 2 | G33: ='Basic Rates'!$E$70 -> 6 | H33: =G33*F33 -> 12
B34: 1.0599999 | C34: 1 1/2" Planks | D34: M-139 | E34: Sq.ft | F34: 16 | G34: ='Basic Rates'!$E$142 -> 140 | H34: =G34*F34 -> 2240
B35: 1.0700001 | C35: 1" Planks | D35: M-139a | E35: Sq.ft | F35: 7 | G35: ='Basic Rates'!$E$143 -> 110 | H35: =G35*F35 -> 770
B36: 1.08 | C36: Carpenter | D36: L-008 | E36: Day | F36: 6 | G36: ='Basic Rates'!$J$11 -> 3500 | H36: =G36*F36 -> 21000
B37: 1.09 | C37: U / SK Labourer | D37: L-007 | E37: Day | F37: 2 | G37: ='Basic Rates'!$J$10 -> 2300 | H37: =G37*F37 -> 4600
D38: Total for | E38: =$F$27 -> 28 | F38: =$G$27 -> Sq.ft | H38: =SUM(H29:H37) -> 30864
D39: Rate for 1 | E39: =$G$27 -> Sq.ft | H39: =H38/F27 -> 1102.2857
D40: Rate(Say) | H40: =ROUND(H39,0) -> 1102
A42: 11.A.03 | C42: Plywood door single hung 3' 1-1/2" x 6' 11-1/2" overall with frame having 1-1/4" thick sash and 3 1/4" x 2 1/4" frame (Glazing, Ironmongory and painting measured separately)
E43: Analysis for | F43: 21.75 | G43: Sq.ft
B44: No | C44: Item Description | D44: Item Ref | E44: Unit | F44: Quantity | G44: Rate | H44: Amount
B45: 1.01 | C45: 4"X3" Timber | D45: M-138 | E45: Cu.ft | F45: 1.8 | G45: ='Basic Rates'!$E$141 -> 1300 | H45: =G45*F45 -> 2340
B46: 1.02 | C46: Spur Stone | D46: M-118 | E46: No | F46: 2 | G46: ='Basic Rates'!$E$121 -> 15 | H46: =G46*F46 -> 30
B47: 1.03 | C47: Fibre / Plastic Plugs | D47: M-045 | E47: No | F47: 6 | G47: ='Basic Rates'!$E$48 -> 1.5 | H47: =G47*F47 -> 9
...

Sheet 12
A2: 12. Plumbing & Drainage
A4: 12.01 | C4: 1/2 " Diameter PVC pipes fixed to walls (Specials paid separately)
E5: Analysis for | F5: 10 | G5: L.ft
B6: No | C6: Item Description | D6: Item Ref | E6: Unit | F6: Quantity | G6: Rate | H6: Amount
B7: 1.01 | C7: 1/2" PVC Pipes | D7: M-095 | E7: L.ft | F7: 13 | G7: ='Basic Rates'!E98 -> 7.5 | H7: =G7*F7 -> 97.5 | J7: 1/2 " | K7: 20mm dia pipe
B8: 1.02 | C8: 1 " Clips and Nails | D8: M-028 | E8: No | F8: 3 | G8: ='Basic Rates'!E31 -> 7 | H8: =G8*F8 -> 21 | J8: 3/4" | K8: 25mm dia pipe
B9: 1.03 | C9: Solvent Cement | D9: M-117 | E9: Grms | F9: 2 | G9: ='Basic Rates'!$E$120 -> 1.4 | H9: =G9*F9 -> 2.8 | J9: 1" | K9: 32mm dia pipe
B10: 1.04 | C10: Plumber | D10: L-002 | E10: Day | F10: 0.125 | G10: ='Basic Rates'!$J$5 -> 3500 | H10: =G10*F10 -> 437.5 | J10: 11/4" | K10: 40mm dia pipe
B11: 1.05 | C11: U / SK Labourer | D11: L-007 | E11: Day | F11: 0.125 | G11: ='Basic Rates'!$J$10 -> 2300 | H11: =G11*F11 -> 287.5 | J11: 11/2" | K11: 50mm dia pipe
D12: Total for | E12: =$F$5 -> 10 | F12: =$G$5 -> L.ft | H12: =SUM(H7:H11) -> 846.3 | J12: 2" | K12: 63mm dia pipe
D13: Rate for 1 | E13: =$G$5 -> L.ft | H13: =H12/E12 -> 84.63 | J13: 21/2" | K13: 75mm dia pipe
D14: Rate(Say) | G14: 1 L.ft | H14: =ROUND(H13,0) -> 85 | J14: 3" | K14: 90mm dia pipe
A16: 12.02 | C16: 3/4 " Diameter PVC pipes fixed to walls (Specials paid separately)
E17: Analysis for | F17: 10 | G17: L.ft
B18: No | C18: Item Description | D18: Item Ref | E18: Unit | F18: Quantity | G18: Rate | H18: Amount
B19: 1.01 | C19: 3/4" PVC Pipes | D19: M-098 | E19: L.ft | F19: 13 | G19: ='Basic Rates'!E101 -> 14 | H19: =G19*F19 -> 182
B20: 1.02 | C20: 1 " Clips and Nails | D20: M-028 | E20: No | F20: 3 | G20: ='Basic Rates'!E31 -> 7 | H20: =G20*F20 -> 21
B21: 1.03 | C21: Solvent Cement | D21: M-117 | E21: Grms | F21: 3 | G21: ='Basic Rates'!$E$120 -> 1.4 | H21: =G21*F21 -> 4.2
B22: 1.04 | C22: Plumber | D22: L-002 | E22: Day | F22: 0.125 | G22: ='Basic Rates'!$J$5 -> 3500 | H22: =G22*F22 -> 437.5
B23: 1.05 | C23: U / SK Labourer | D23: L-007 | E23: Day | F23: 0.125 | G23: ='Basic Rates'!$J$10 -> 2300 | H23: =G23*F23 -> 287.5
D24: Total for | E24: =$F$17 -> 10 | F24: =$G$17 -> L.ft | H24: =SUM(H19:H23) -> 932.2
D25: Rate for 1 | E25: =$G$17 -> L.ft | H25: =H24/E24 -> 93.22
D26: Rate(Say) | G26: 1 L.ft | H26: =ROUND(H25,0) -> 93
A28: 12.03 | C28: 1 " Diameter PVC pipes fixed to walls (Specials paid separately)
E29: Analysis for | F29: 100 | G29: L.ft
B30: No | C30: Item Description | D30: Item Ref | E30: Unit | F30: Quantity | G30: Rate | H30: Amount
B31: 1.01 | C31: 1" PVC Pipes | D31: M-094 | E31: L.ft | F31: 100 | G31: ='Basic Rates'!E97 -> 21 | H31: =G31*F31 -> 2100
B32: 1.02 | C32: Allow 5% of Items ( 1.01 ) for Wastage | D32: - | E32: - | F32: - | G32: - | H32: =H31*5/100 -> 105
B33: 1.03 | C33: 1" PVC Sockets | D33: M-077 | E33: No | F33: 8 | G33: ='Basic Rates'!E80 -> 14 | H33: =G33*F33 -> 112
B34: 1.04 | C34: Solvent Cement | D34: M-117 | E34: Grms | F34: 32 | G34: ='Basic Rates'!$E$120 -> 1.4 | H34: =G34*F34 -> 44.8
B35: 1.05 | C35: 1 " Clips and Nails | D35: M-028 | E35: No | F35: 35 | G35: ='Basic Rates'!E31 -> 7 | H35: =G35*F35 -> 245
B36: 1.0599999 | C36: Plumber | D36: L-002 | E36: Day | F36: 0.5 | G36: ='Basic Rates'!$J$5 -> 3500 | H36: =G36*F36 -> 1750
B37: 1.0700001 | C37: U / SK Labourer | D37: L-007 | E37: Day | F37: 0.5 | G37: ='Basic Rates'!$J$10 -> 2300 | H37: =G37*F37 -> 1150
D38: Total for | E38: =$F$29 -> 100 | F38: =$G$29 -> L.ft | H38: =SUM(H31:H37) -> 5506.8
D39: Rate for 1 | E39: =$G$29 -> L.ft | H39: =H38/E38 -> 55.068
D40: Rate(Say) | G40: 1 L.ft | H40: =ROUND(H39,0) -> 55
A42: 12.04 | C42: 1 1/4"Diameter PVC pipes fixed to walls (Specials paid separately)
E43: Analysis for | F43: 100 | G43: L.ft
B44: No | C44: Item Description | D44: Item Ref | E44: Unit | F44: Quantity | G44: Rate | H44: Amount
B45: 1.01 | C45: 1 1/4" PVC Pipes | D45: M-093 | E45: L.ft | F45: 100 | G45: ='Basic Rates'!E96 -> 32 | H45: =G45*F45 -> 3200
...

Sheet 14
A2: 14. Tilling
B4: A. | C4: Wall Tilling
B5: B. | C5: Floor Tilling
A7: Wall Tilling
A9: 14.A.01 | C9: Glazed tiles fixed to walls including bedding in cement mortar 1:2 and raking in ground floor.(Specials measured separately)
E10: Analysis for | F10: 1 | G10: Sqr
B11: No | C11: Item Description | D11: Item Ref | E11: Unit | F11: Quantity | G11: Rate | H11: Amount
B12: 1.01 | C12: Glazed Tiles (6''x6") | D12: M-155 | E12: No | F12: 400 | G12: ='Basic Rates'!E159 -> 75 | H12: =G12*F12 -> 30000
B13: 1.02 | C13: Allow 10% of Items ( 1.01 ) for Wastage | D13: - | E13: - | F13: - | G13: - | H13: =(H12)*10/100 -> 3000
B14: 1.03 | C14: Cement | D14: M-026 | E14: Bag | F14: 2.5 | G14: ='Basic Rates'!$E$29 -> 2400 | H14: =G14*F14 -> 6000
B15: 1.04 | C15: Sand | D15: M-113 | E15: Cu | F15: 0.11 | G15: ='Basic Rates'!$E$116 -> 18000 | H15: =G15*F15 -> 1980
B16: 1.05 | C16: White Cement | D16: M-159 | E16: Lbs | F16: 1 | G16: ='Basic Rates'!$E$163 -> 17.5 | H16: =G16*F16 -> 17.5
B17: 1.0599999 | C17: Mason | D17: L-009 | E17: Day | F17: 4 | G17: ='Basic Rates'!$J$12 -> 3500 | H17: =G17*F17 -> 14000
B18: 1.0700001 | C18: U / SK Labourer | D18: L-007 | E18: Day | F18: 4 | G18: ='Basic Rates'!$J$10 -> 2300 | H18: =G18*F18 -> 9200
B19: 1.08 | C19: U / SK Labourer | D19: L-007 | E19: Day | F19: 0.25 | G19: ='Basic Rates'!$J$10 -> 2300 | H19: =G19*F19 -> 575
D20: Total for | E20: =$F$31 -> 1 | F20: =$G$31 -> Sqr | H20: =SUM(H12:H19) -> 64772.5
D21: Rate for 1 | E21: =$G$31 -> Sqr | H21: =H20/F10 -> 64772.5
D22: Rate(Say) | G22: 1Sq | H22: =ROUND(H21,0) -> 64773
D23: Rate(Say) | G23: 1ft2 | H23: =H22/100 -> 647.73
D24: Rate(Say) | G24: 1m2 | H24: =H23*10.76 -> 6969.5748
D25: Ground floor | G25: 1m2 | H25: =H24 -> 6969.5748
D26: First Floor | G26: 1m2 | H26: =H25*1.1 -> 7666.5323
D27: Second Floor | G27: 1m2 | H27: =H26*1.1 -> 8433.1855
D28: Third Floor | G28: 1m2 | H28: =H27*1.1 -> 9276.5041
A30: 14.A.02 | C30: Glazed tiles fixed to walls including bedding in cement mortar 1:2 and raking in ground floor.(Specials measured separately)
E31: Analysis for | F31: 1 | G31: Sqr
B32: No | C32: Item Description | D32: Item Ref | E32: Unit | F32: Quantity | G32: Rate | H32: Amount
B33: 1.01 | C33: Glazed Tiles (8''x12") | D33: M-156 | E33: No | F33: 150 | G33: ='Basic Rates'!E160 -> 100 | H33: =G33*F33 -> 15000
B34: 1.02 | C34: Allow 10% of Items ( 1.01 ) for Wastage | D34: - | E34: - | F34: - | G34: - | H34: =(H33)*10/100 -> 1500
B35: 1.03 | C35: Cement | D35: M-026 | E35: Bag | F35: 2.5 | G35: ='Basic Rates'!$E$29 -> 2400 | H35: =G35*F35 -> 6000
B36: 1.04 | C36: Sand | D36: M-113 | E36: Cu | F36: 0.11 | G36: ='Basic Rates'!$E$116 -> 18000 | H36: =G36*F36 -> 1980
B37: 1.05 | C37: White Cement | D37: M-159 | E37: Lbs | F37: 1 | G37: ='Basic Rates'!$E$163 -> 17.5 | H37: =G37*F37 -> 17.5
B38: 1.0599999 | C38: Mason | D38: L-009 | E38: Day | F38: 4 | G38: ='Basic Rates'!$J$12 -> 3500 | H38: =G38*F38 -> 14000
B39: 1.0700001 | C39: U / SK Labourer | D39: L-007 | E39: Day | F39: 4 | G39: ='Basic Rates'!$J$10 -> 2300 | H39: =G39*F39 -> 9200
B40: 1.08 | C40: U / SK Labourer | D40: L-007 | E40: Day | F40: 0.25 | G40: ='Basic Rates'!$J$10 -> 2300 | H40: =G40*F40 -> 575
D41: Total for | E41: =$F$31 -> 1 | F41: =$G$31 -> Sqr | H41: =SUM(H33:H40) -> 48272.5
D42: Rate for 1 | E42: =$G$31 -> Sqr | H42: =H41/F31 -> 48272.5
D43: Rate(Say) | G43: 1Sq | H43: =ROUND(H42,0) -> 48273
D44: Rate(Say) | G44: 1ft2 | H44: =H43/100 -> 482.73
D45: Rate(Say) | G45: 1m2 | H45: =H44*10.76 -> 5194.1748
...

Sheet 13
A2: 13. Plastering
B4: A. | C4: Wall Plastering
B5: B. | C5: Rendering
B6: C. | C6: Sofit Plastering
B7: D. | C7: Skirting
D11: Wall Plastering
A13: 13.A.01 | C13: 5/8" thick plastering to wall in Cement and sand 1:3 including Cement floating
E14: Analysis for | F14: 1 | G14: Sqr
B15: No | C15: Item Description | D15: Item Ref | E15: Unit | F15: Quantity | G15: Rate | H15: Amount
B16: 1.01 | C16: Cement | D16: M-026 | E16: Bag | F16: 1.4 | G16: ='Basic Rates'!$E$29 -> 2400 | H16: =F16*G16 -> 3360
B17: 1.02 | C17: Sand | D17: M-113 | E17: Cu | F17: 0.06 | G17: ='Basic Rates'!$E$116 -> 18000 | H17: =F17*G17 -> 1080
B18: 1.03 | C18: Water | D18: M-157 | E18: Gal | F18: 10 | G18: ='Basic Rates'!$E$161 -> 0.3 | H18: =F18*G18 -> 3
B19: 1.04 | C19: Mason | D19: L-009 | E19: Day | F19: 1 | G19: ='Basic Rates'!$J$12 -> 3500 | H19: =F19*G19 -> 3500
B20: 1.05 | C20: U / SK Labourer | D20: L-007 | E20: Day | F20: 1.5 | G20: ='Basic Rates'!$J$10 -> 2300 | H20: =F20*G20 -> 3450
B21: 1.0599999 | C21: Allow 3% of Items ( 1.04, 1.05 ) for Scaffolding | D21: - | E21: - | F21: - | G21: - | H21: =(H19+H20)*3/100 -> 208.5
D22: Total for | E22: =F14 -> 1 | F22: =$G$14 -> Sqr | H22: =SUM(H16:H21) -> 11601.5
D23: Rate for 1 | E23: =$G$14 -> Sqr | H23: =H22/E22 -> 11601.5
D24: Rate(Say) | G24: 1Sq | H24: =ROUND(H23,0) -> 11602
D25: Rate(Say) | G25: 1ft2 | H25: =H24/100 -> 116.02
D26: Rate(Say) | G26: 1m2 | H26: =H25*10.76 -> 1248.3752
A28: 13.A.02 | C28: 5/8" thick to wall in cement and sand 1:5 finished semi-rough with wooden float.
E29: Analysis for | F29: 1 | G29: Sqr
B30: No | C30: Item Description | D30: Item Ref | E30: Unit | F30: Quantity | G30: Rate | H30: Amount
B31: 1.01 | C31: Cement | D31: M-026 | E31: Bag | F31: 0.8 | G31: ='Basic Rates'!$E$29 -> 2400 | H31: =G31*F31 -> 1920
B32: 1.03 | C32: Sand | D32: M-113 | E32: Cu | F32: 0.07 | G32: ='Basic Rates'!$E$116 -> 18000 | H32: =G32*F32 -> 1260
B33: 1.04 | C33: Water | D33: M-157 | E33: Gal | F33: 10 | G33: ='Basic Rates'!$E$161 -> 0.3 | H33: =G33*F33 -> 3
B34: 1.05 | C34: Mason | D34: L-009 | E34: Day | F34: 1 | G34: ='Basic Rates'!$J$12 -> 3500 | H34: =G34*F34 -> 3500
B35: 1.0599999 | C35: U / SK Labourer | D35: L-007 | E35: Day | F35: 1.25 | G35: ='Basic Rates'!$J$10 -> 2300 | H35: =G35*F35 -> 2875
D36: Total for | E36: =F29 -> 1 | F36: =$G$14 -> Sqr | H36: =SUM(H31:H35) -> 9558
D37: Rate for 1 | E37: =$G$14 -> Sqr | H37: =H36/E36 -> 9558
D38: Rate(Say) | G38: 1Sq | H38: =ROUND(H37,0) -> 9558
D39: Rate(Say) | G39: 1ft2 | H39: =H38/100 -> 95.58
D40: Rate(Say) | G40: 1m2 | H40: =H39*10.76 -> 1028.4408
D41: Ground floor - First Floor | G41: 1m2 | H41: =H40 -> 1028.4408
D42: First Floor - Second Floor | G42: 1m2 | H42: =H41*1.1 -> 1131.2849
D43: Second Floor - Third Floor | G43: 1m2 | H43: =H42*1.1 -> 1244.4134
D44: Third Floor - Fourth Floor | G44: 1m2 | H44: =H43*1.1 -> 1368.8547
A46: 13.A.03 | C46: 5/8" thick to wall in lime cement and sand 1:1:5 finished semi-rough with wooden float.
E47: Analysis for | F47: 1 | G47: Sq
B48: No | C48: Item Description | D48: Item Ref | E48: Unit | F48: Quantity | G48: Rate | H48: Amount
...

Sheet 15
A2: 15. Ceiling
A4: 15.01 | C4: Timber Framework for 4' 0"x4' 0" flat asbestos ceiling (Sheet Measured separately) Comprising of 4"x2" joists and 2"x2" bearers in class 1 timber
E5: Analysis for | F5: 1.95 | G5: Sqrs
B6: No | C6: Item Description | D6: Item Ref | E6: Unit | F6: Quantity | G6: Rate | H6: Amount
B7: 1.01 | C7: Timber Class I | D7: M-136 | E7: Cu.ft | F7: 8 | G7: ='Basic Rates'!E139 -> 1200 | H7: =G7*F7 -> 9600
B8: 1.02 | C8: 2" Nails | D8: M-072 | E8: Lbs | F8: 1 | G8: ='Basic Rates'!E75 -> 50 | H8: =G8*F8 -> 50
B9: 1.03 | C9: Fibre / Plastic Plugs | D9: M-045 | E9: No | F9: 26 | G9: ='Basic Rates'!E48 -> 1.5 | H9: =G9*F9 -> 39
B10: 1.04 | C10: Cement | D10: M-026 | E10: Bag | F10: 0.23 | G10: ='Basic Rates'!$E$29 -> 2400 | H10: =G10*F10 -> 552
B11: 1.05 | C11: Sand | D11: M-113 | E11: Cu | F11: 0.02 | G11: ='Basic Rates'!$E$116 -> 18000 | H11: =G11*F11 -> 360
B12: 1.0599999 | C12: Brush 2" | D12: M-022 | E12: No | F12: 0.25 | G12: ='Basic Rates'!E25 -> 900 | H12: =G12*F12 -> 225
B13: 1.0700001 | C13: Tarnap | D13: M-119 | E13: Gal | F13: 0.333 | G13: ='Basic Rates'!E122 -> 450 | H13: =G13*F13 -> 149.85
B14: 1.08 | C14: Carpenter | D14: L-008 | E14: Day | F14: 2.5 | G14: ='Basic Rates'!$J$11 -> 3500 | H14: =G14*F14 -> 8750
B15: 1.09 | C15: Mason | D15: L-009 | E15: Day | F15: 0.5 | G15: ='Basic Rates'!$J$12 -> 3500 | H15: =G15*F15 -> 1750
B16: 1.1 | C16: U / SK Labourer | D16: L-007 | E16: Day | F16: 1.5 | G16: ='Basic Rates'!$J$10 -> 2300 | H16: =G16*F16 -> 3450
B17: 1.11 | C17: Allow 3% of Items ( 1.08, 1.09, 1.10 ) for Scaffolding | D17: - | E17: - | F17: - | G17: - | H17: =(H14+H15+H16)*3/100 -> 418.5
D18: Total for | E18: =$F$5 -> 1.95 | F18: =$G$5 -> Sqrs | H18: =SUM(H7:H17) -> 25344.35
D19: Rate for 1 | E19: =$G$5 -> Sqrs | H19: =H18/F5 -> 12997.103
D20: Rate(Say) | H20: =ROUND(H19,0) -> 12997
A22: 15.02 | C22: Horizontal ceiling lining using 4' 0"x4' 0" flat asbestos cement sheets fixed with and including beading and cove mouldings on timber framework(Timber, framework, painting m/separately)
E23: Analysis for | F23: 1.95 | G23: Sqrs
B24: No | C24: Item Description | D24: Item Ref | E24: Unit | F24: Quantity | G24: Rate | H24: Amount
B25: 1.01 | C25: Flat Asbestos Sheets | D25: M-048 | E25: Sq.ft | F25: 210 | G25: ='Basic Rates'!E51 -> 15 | H25: =G25*F25 -> 3150
B26: 1.02 | C26: 2"X2" halmilla Cove Moulding | D26: M-145 | E26: Sq.ft | F26: 60 | G26: ='Basic Rates'!E149 -> 35 | H26: =G26*F26 -> 2100
B27: 1.03 | C27: 1 1/2"X1/2" Halmilla Beadings | D27: M-134 | E27: L.ft | F27: 125 | G27: ='Basic Rates'!E137 -> 12 | H27: =G27*F27 -> 1500
B28: 1.04 | C28: 1/4" clout Nails | D28: M-033 | E28: lbs | F28: 0.25 | G28: ='Basic Rates'!E36 -> 25 | H28: =G28*F28 -> 6.25
B29: 1.05 | C29: Brass Screws 1 1/2" | D29: M-015 | E29: No | F29: 96 | G29: ='Basic Rates'!E18 -> 3.75 | H29: =G29*F29 -> 360
B30: 1.0599999 | C30: Carpenter | D30: L-008 | E30: Day | F30: 1.5 | G30: ='Basic Rates'!$J$11 -> 3500 | H30: =G30*F30 -> 5250
B31: 1.0700001 | C31: U / SK Labourer | D31: L-007 | E31: Day | F31: 2 | G31: ='Basic Rates'!$J$10 -> 2300 | H31: =G31*F31 -> 4600
B32: 1.08 | C32: Allow 3% of Items ( 1.06, 1.07 ) for Scaffolding | D32: - | E32: - | F32: - | G32: - | H32: =(H30+H31)*3/100 -> 295.5
D33: Total for | E33: =$F$23 -> 1.95 | F33: =$G$23 -> Sqrs | H33: =SUM(H25:H32) -> 17261.75
D34: Rate for 1 | E34: =$G$23 -> Sqrs | H34: =H33/F23 -> 8852.1795
D35: Rate(Say) | H35: =ROUND(H34,0) -> 8852
A37: 15.03 | C37: 3/4" thick tongued and grooved Lunumidella ceiling boards fixed horizontal on 4"X2" class I timber Joists at 2' 0" centres with 1 1/2 " Brass Nails
E38: Analysis for | F38: 1.95 | G38: Sqrs
B39: No | C39: Item Description | D39: Item Ref | E39: Unit | F39: Quantity | G39: Rate | H39: Amount
B40: 1.01 | C40: 4" x 2" Timber Joists | D40: M-146 | E40: L.ft | F40: 115 | G40: ='Basic Rates'!E150 -> 65 | H40: =G40*F40 -> 7475
B41: 1.02 | C41: 6" x 3/4" Lunumidella Ceiling Planks. | D41: M-135 | E41: Sq.ft | F41: 215 | G41: ='Basic Rates'!E138 -> 28 | H41: =G41*F41 -> 6020
B42: 1.03 | C42: Cement | D42: M-026 | E42: Bag | F42: 0.027 | G42: ='Basic Rates'!$E$29 -> 2400 | H42: =G42*F42 -> 64.8
B43: 1.04 | C43: Sand | D43: M-113 | E43: Cu | F43: 0.04 | G43: ='Basic Rates'!$E$116 -> 18000 | H43: =G43*F43 -> 720
B44: 1.05 | C44: 1 1/2 brass Nails | D44: M-012 | E44: lbs | F44: =4/0.454 -> 8.8105727 | G44: ='Basic Rates'!E15 -> 50 | H44: =G44*F44 -> 440.52863
...

Sheet 16
A2: 16. Painting
B4: A. | C4: Wall
B5: B. | C5: Sofit
B6: C. | C6: Wood
B7: Anti-Termite treatment on excavated foundation and compacted soil under floors. | C7: Steel
D8: Wall
A10: 16.A.01 | C10: Preparing and apply one coat of Alkali resistant primer and two coats of emulsion paint to walls.
E11: Analysis for | F11: 1 | G11: Sqr
B12: No | C12: Item Description | D12: Item Ref | E12: Unit | F12: Quantity | G12: Rate | H12: Amount
B13: 1.01 | C13: Primer | D13: M-075 | E13: litre | F13: 0.9 | G13: ='Basic Rates'!E78 -> 805 | H13: =G13*F13 -> 724.5
B14: 1.02 | C14: Emulsion Paint | D14: M-043 | E14: litre | F14: 1.4 | G14: ='Basic Rates'!E46 -> 2670 | H14: =G14*F14 -> 3738 | J14: =32000/20 -> 1600
B15: 1.03 | C15: Water | D15: M-157 | E15: Gal | F15: 0.1 | G15: ='Basic Rates'!$E$161 -> 0.3 | H15: =G15*F15 -> 0.03
B16: 1.04 | C16: 6" Brush | D16: M-021 | E16: No | F16: 0.1 | G16: ='Basic Rates'!$E$24 -> 2350 | H16: =G16*F16 -> 235
B17: 1.05 | C17: Sand Papers | D17: M-114 | E17: Sheet | F17: 2 | G17: ='Basic Rates'!$E$117 -> 250 | H17: =G17*F17 -> 500
B18: 1.0599999 | C18: Painter | D18: L-001 | E18: Day | F18: 1.25 | G18: ='Basic Rates'!$J$4 -> 4000 | H18: =G18*F18 -> 5000
B19: 1.0699999 | C19: Allow 3% of Items (1.06) for Scaffolding | D19: - | E19: - | F19: - | G19: - | H19: =(H18)*3/100 -> 150
D20: Total for | E20: =$F$11 -> 1 | F20: =$G$11 -> Sqr | H20: =SUM(H13:H19) -> 10347.53
D21: Rate for 1 | E21: =$G$11 -> Sqr | H21: =H20/E20 -> 10347.53
D22: Rate(Say) | G22: 1 Sq | H22: =ROUND(H21,0) -> 10348
D23: Rate(Say) | G23: 1ft2 | H23: =H22/100 -> 103.48
D24: Rate(Say) | G24: 1m2 | H24: =H23*10.76 -> 1113.4448
D25: Ground floor | G25: 1m2 | H25: =H24 -> 1113.4448
D26: First Floor | G26: 1m2 | H26: =H25*1.1 -> 1224.7893
D27: Second Floor | G27: 1m2 | H27: =H26*1.1 -> 1347.2682
D28: Third Floor | G28: 1m2 | H28: =H27*1.1 -> 1481.995
A30: 16.A.02 | C30: Painting walls with emulsion paint (2 Coats)
E31: Analysis for | F31: 1 | G31: Sqr
B32: No | C32: Item Description | D32: Item Ref | E32: Unit | F32: Quantity | G32: Rate | H32: Amount
B33: 1.01 | C33: Emulsion Paint - first coat | D33: M-043 | E33: litre | F33: 0.757 | G33: ='Basic Rates'!$E$46 -> 2670 | H33: =G33*F33 -> 2021.19
B34: 1.02 | C34: Emulsion Paint - Second coat | D34: M-043 | E34: litre | F34: 0.649 | G34: ='Basic Rates'!$E$46 -> 2670 | H34: =G34*F34 -> 1732.83
B35: 1.03 | C35: 6" Brush | D35: M-021 | E35: No | F35: 0.1 | G35: ='Basic Rates'!E24 -> 2350 | H35: =G35*F35 -> 235
