Workbook

Sheet Construction Accounting
E2: info@vegahomes.lk | H2: CONSTRUCTION ACCOUNTING
E3: www.vegahomes.lk
E4: No 494, Puttalam Road, Kurunegala
E5: +9471 274 1577, +947777 20 888
B9: Project Information | K9: Income | L9: Actual | M9: Budget | N9: Variances
B10: Project Name | D10: Commercial Office Building | K10: Contract Amount | L10: 35000000 | M10: 30000000 | N10: =L10-M10 -> 5000000
B11: Project ID | D11: VH-001 | K11: Change Orders | L11: 2500000 | M11: 1000000 | N11: =L11-M11 -> 1500000
B12: Project Manager | K12: Progress Payments | L12: 26000000 | M12: 3500000 | N12: =L12-M12 -> 22500000
B13: Project Start Date | K13: Retainage Released | L13: 1000000 | M13: 280000 | N13: =L13-M13 -> 720000
B14: Project End Date | N14: =L14-M14 -> 0
N15: =L15-M15 -> 0
B16: Total Actual Income | E16: Total Actual Expenses | H16: Net Income | N16: =L16-M16 -> 0
N17: =L17-M17 -> 0
B18: =Accounts!D262 -> 6250000 | E18: =Accounts!N262 -> 5194547 | H18: =B18-E18 -> 1055453 | N18: =L18-M18 -> 0
K19: Total Income | L19: =SUM(L10:L18) -> 64500000 | M19: =SUM(M10:M18) -> 34780000 | N19: =L19-M19 -> 29720000
B21: INCOME | K21: Expenses | L21: Actual | M21: Budget | N21: Variances
K22: Direct Costs
C23: Actual | D23: =L19 -> 64500000 | K23: Labor | L23: =GETPIVOTDATA("Total",Sheet1!$B$15,"Category","Labour") -> 497300 | M23: 48000 | N23: =L23-M23 -> 449300
C24: Budget | D24: =M19 -> 34780000 | K24: Materials | L24: =GETPIVOTDATA("Total",Sheet1!$B$15,"Category","Material") -> 989735 | M24: 32000 | N24: =L24-M24 -> 957735
K25: Equipment | L25: =GETPIVOTDATA("Total",Sheet1!$B$15,"Category","Machinery") -> 26156 | M25: 14000 | N25: =L25-M25 -> 12156
K26: Subcontractor Costs | L26: =GETPIVOTDATA("Total",Sheet1!$B$15,"Category","Sub Contractor") -> 106080 | M26: 18000 | N26: =L26-M26 -> 88080
K27: Other Direct Costs | L27: =GETPIVOTDATA("Total",Sheet1!$B$15,"Category","Other") -> 3366026 | M27: 6000 | N27: =L27-M27 -> 3360026
N28: =L28-M28 -> 0
N29: =L29-M29 -> 0
N30: =L30-M30 -> 0
B31: EXPENSES | K31: Indirect Costs
K32: Overhead | L32: 10000 | M32: 9000 | N32: =L32-M32 -> 1000
K33: Administrative Expenses | L33: 8000 | M33: 7500 | N33: =L33-M33 -> 500
K34: Insurance | L34: 3000 | M34: 3200 | N34: =L34-M34 -> -200
C35: Actual | D35: =L39 -> 5008297 | K35: Permits and Fees | L35: 2000 | M35: 1800 | N35: =L35-M35 -> 200
C36: Budget | D36: =M39 -> 139500 | N36: =L36-M36 -> 0
N37: =L37-M37 -> 0
N38: =L38-M38 -> 0
K39: Total Expenses | L39: =SUM(L23:L38) -> 5008297 | M39: =SUM(M23:M38) -> 139500 | N39: =SUM(N23:N38) -> 4868797

Sheet Sheet1
B15: Sum of Total | C15: Column Labels
B16: Row Labels | C16: Labour | D16: Machinery | E16: Material | F16: Sub Contractor | G16: Transport | H16: Other | I16: Grand Total
B17: 3/4" Metal Cube 01 | E17: 28500 | H17: 8500 | I17: 37000
B18: 6"x9" Struips | H18: 1190 | I18: 1190
B19: A.C.K Colour House | H19: 21450 | I19: 21450
B20: A.K.Hardware | H20: 4500 | I20: 4500
B21: Ajantha(Mason)/Advance | C21: 305800 | H21: 900778 | I21: 1206578
B22: Amila(Electrical)/Advance | C22: 61000 | I22: 61000
B23: Anthony's Hw | H23: 90230 | I23: 90230
B24: Binding 2Kg | H24: 800 | I24: 800
B25: Bricks = 3000Nr | H25: 99000 | I25: 99000
B26: Cainz Hw | E26: 2150 | H26: 181651 | I26: 183801
B27: Card Board | H27: 1500 | I27: 1500
B28: Cement | E28: 10780 | H28: 75300 | I28: 86080
B29: Cement Bag 06 Nr | E29: 12600 | I29: 12600
B30: Central Hw | E30: 43580 | I30: 43580
B31: Chamidu Timbers | E31: 6880 | H31: 2250 | I31: 9130
B32: Chathuranga Hw | E32: 4510 | H32: 27240 | I32: 31750
B33: Chuti Mahaththaya | F33: 17500 | H33: 50000 | I33: 67500
B34: Dewmith Construction | F34: 34500 | I34: 34500
B35: Electrical Items | H35: 1710 | I35: 1710
B36: Excavator | D36: 13500 | I36: 13500
B37: Finex Engineering | E37: 5750 | H37: 71542 | I37: 77292
B38: Foods -Mr.Nazir | F38: 2520 | I38: 2520
B39: Hardware Item | H39: 650 | I39: 650
B40: Jagath(Mason)/Salary | H40: 23200 | I40: 23200
B41: Jagath(Mason)/Salary | C41: 29000 | I41: 29000
B42: Jagath(Mason)/Salary (Slab Repairing) | C42: 5800 | I42: 5800
B43: Jayalanka Hw | H43: 10250 | I43: 10250
B44: Jenerator | H44: 10800 | I44: 10800
B45: K.S.De Silva and Son | H45: 4330 | I45: 4330
B46: Lanka Tiles | H46: 71218 | I46: 71218
B47: Linko Construction | D47: 12656 | H47: 100000 | I47: 112656
B48: Lion Plywood | E48: 38400 | I48: 38400
B49: M City Hw | E49: 1000 | I49: 1000
B50: M.M Hardware | H50: 1150 | I50: 1150
B51: Mahagalkadawala Hw | E51: 286005 | H51: 90972 | I51: 376977
B52: Manjula(Welder)/Advance | H52: 15000 | I52: 15000
B53: Modern Hardware | E53: 3880 | I53: 3880
B54: Mr.Mahiti | G54: 5000 | I54: 5000
...

Sheet Accounts
A1: Mr. Lalith Suranga (Millawa/New Works) | O1: =SUM(O6:O261) -> 500000 | P1: =SUM(P6:P261) -> 173500 | Q1: =SUM(Q6:Q261) -> 0 | R1: =SUM(R6:R261) -> 0 | S1: =SUM(S6:S261) -> 57500 | T1: =SUM(T6:T261) -> 0 | U1: =SUM(U6:U261) -> 13500 | V1: =SUM(V6:V261) -> 5000 | ... Z1: =SUM(Z6:Z261) -> 0
A3: INCOME BALANCE STATEMENT
A5: Date | B5: Payment No | C5: Amount | D5: Cumulative | E5: Remarks | F5: Date2 | G5: Entry No | H5: Description | I5: Category | J5: Memo | K5: Stage | L5: BOQ Item | M5: Total | N5: Cumulative2 | O5: Outstanding Payments | P5: Transport | Q5: Labour / Sub Contractor | R5: Site Visit | S5: Machinery | T5: Minor Material | U5: Major Material | V5: Service Charge | W5: Utility Bills | X5: Food & Beverages | Y5: Fuel | Z5: Others
A6: 45107 | B6: 1 | C6: 500000 | D6: 500000 | E6: Cash | F6: 45091 | G6: 1 | H6: Site Visit | I6: Transport | J6: 06/1103 | K6: Stage-01 | L6: Tile Works | M6: 5000 | N6: =M6 -> 5000 | P6: 5000
A7: 45134 | B7: 1 | C7: 500000 | D7: =D6+C7 -> 1000000 | E7: Bank | F7: 45091 | G7: 2 | H7: Mr.Mahiti | I7: Transport | J7: 06/1104 | K7: Stage-02 | L7: Plastering Works | M7: 5000 | N7: =M7+N6 -> 10000 | V7: 5000
A8: 45204 | B8: 1 | C8: 500000 | D8: =D7+C8 -> 1500000 | E8: Online | F8: 45105 | G8: 3 | H8: Mahagalkadawala Hw | I8: Material | J8: 06/1118 | K8: Stage-03 | L8: Painting Works | M8: 8400 | N8: =M8+N7 -> 18400
A9: 45211 | B9: 1 | C9: 500000 | D9: =D8+C9 -> 2000000 | E9: Bank | F9: 45104 | G9: 4 | H9: Ajantha(Mason)/Advance | I9: Labour | J9: 06/1120 | K9: Stage-04 | L9: Aluminium Works | M9: 5000 | N9: =M9+N8 -> 23400
A10: 45231 | B10: 1 | C10: 1500000 | D10: =D9+C10 -> 3500000 | E10: Online | F10: 45103 | G10: 5 | H10: Site Visit | I10: Transport | J10: 06/1126 | K10: Stage-05 | L10: Timber Works | M10: 2500 | N10: =M10+N9 -> 25900 | P10: 2500
A11: 45311 | B11: 1 | C11: 1000000 | D11: =D10+C11 -> 4500000 | E11: Bank | F11: 45106 | G11: 6 | H11: Transport | I11: Transport | J11: 06/1129 | K11: Stage-06 | L11: Steel Works | M11: 5000 | N11: =M11+N10 -> 30900 | P11: 2500
A12: 45350 | B12: 1 | C12: 700000 | D12: =D11+C12 -> 5200000 | E12: Bank | F12: 45104 | G12: 7 | H12: Transport | I12: Transport | J12: 06/1130 | L12: Waterproofing | M12: 5000 | N12: =M12+N11 -> 35900 | P12: 5000
A13: 45362 | B13: 1 | C13: 300000 | D13: =D12+C13 -> 5500000 | E13: Online | F13: 45108 | G13: 8 | H13: Ajantha(Mason)/Advance | I13: Labour | J13: 06/1141 | L13: Roofing | M13: 16300 | N13: =M13+N12 -> 52200
A14: 45389 | B14: 1 | C14: 250000 | D14: =D13+C14 -> 5750000 | E14: Bank | F14: 45108 | G14: 9 | H14: Removing Glass Roof | I14: Labour | J14: 07/1146 | L14: Electrical Works | M14: 8000 | N14: =M14+N13 -> 60200
A15: 45392 | B15: 1 | C15: 500000 | D15: =D14+C15 -> 6250000 | E15: Bank | F15: 45111 | G15: 10 | H15: Transport | I15: Transport | J15: 07/1146 | L15: Masonry Works | M15: 5100 | N15: =M15+N14 -> 65300 | P15: 5100
B16: 1 | F16: 45111 | G16: 11 | H16: Foods -Mr.Nazir | I16: Sub Contractor | J16: 07/1147 | L16: Plumbing Works | M16: 2520 | N16: =M16+N15 -> 67820 | W16: 2520
B17: 1 | F17: 45111 | G17: 12 | H17: Mr.Nazir (Advance Payment) | I17: Sub Contractor | J17: 07/1148 | L17: Rain Gutters | M17: 1000 | N17: =M17+N16 -> 68820
B18: 1 | F18: 45111 | G18: 13 | H18: Transport | I18: Transport | J18: 07/1149 | M18: 5000 | N18: =M18+N17 -> 73820 | P18: 5000
B19: 1 | F19: 45111 | G19: 14 | H19: Chathuranga Hw | I19: Material | J19: 07/1151 | M19: 3160 | N19: =M19+N18 -> 76980
B20: 1 | F20: 45111 | G20: 15 | H20: Multi Hw | I20: Material | J20: 07/1152 | M20: 700 | N20: =M20+N19 -> 77680
B21: 1 | F21: 45112 | G21: 16 | H21: Mr.Nazir-Brick Wall Demolish | I21: Sub Contractor | J21: 07/1154 | M21: 5000 | N21: =M21+N20 -> 82680
B22: 1 | F22: 45112 | G22: 17 | H22: Mr.Nazir | I22: Sub Contractor | J22: 07/1155 | M22: 44000 | N22: =M22+N21 -> 126680
B23: 1 | F23: 45112 | G23: 18 | H23: Transport | I23: Transport | J23: 07/1156 | M23: 6000 | N23: =M23+N22 -> 132680 | P23: 6000
B24: 1 | F24: 45112 | G24: 19 | H24: Mr.Nazir- Foods | I24: Sub Contractor | J24: 07/1157 | M24: 1560 | N24: =M24+N23 -> 134240 | W24: 1560
B25: 1 | F25: 45113 | G25: 20 | H25: Site Visit | I25: Transport | J25: 07/1159 | M25: 2700 | N25: =M25+N24 -> 136940 | P25: 2700
B26: 1 | F26: 45115 | G26: 21 | H26: Nilu(Mason)/Salary | I26: Labour | J26: 07/1172 | M26: 17500 | N26: =M26+N25 -> 154440
B27: 1 | F27: 45119 | G27: 22 | H27: Cement | I27: Material | J27: 07/1183 | M27: 4400 | N27: =M27+N26 -> 158840
B28: 1 | F28: 45119 | G28: 23 | H28: Transport | I28: Transport | J28: 07/1184 | M28: 2500 | N28: =M28+N27 -> 161340 | P28: 2500
B29: 1 | F29: 45120 | G29: 24 | H29: Nilu(Mason)/Advance | I29: Labour | J29: 07/1191 | M29: 1000 | N29: =M29+N28 -> 162340
B30: 1 | F30: 45122 | G30: 25 | H30: Nilu(Mason)/Salary | I30: Labour | J30: 07/1193 | M30: 16400 | N30: =M30+N29 -> 178740
B31: 1 | F31: 45125 | G31: 26 | H31: Site Visit | I31: Transport | J31: 07/1204 | M31: 2500 | N31: =M31+N30 -> 181240 | P31: 2500
B32: 1 | F32: 45127 | G32: 27 | H32: Mahagalkadawala Hw | I32: Material | J32: 07/1211 | M32: 56580 | N32: =M32+N31 -> 237820
B33: 1 | F33: 45127 | G33: 28 | H33: Site Visit | I33: Transport | J33: 07/1215 | M33: 6750 | N33: =M33+N32 -> 244570 | P33: 6750
B34: 1 | F34: 45128 | G34: 29 | H34: Priyantha(u/sk)/Advance | I34: Labour | J34: 07/1216 | M34: 1000 | N34: =M34+N33 -> 245570
B35: 1 | F35: 45128 | G35: 30 | H35: Site Visit | I35: Transport | J35: 07/1217 | M35: 3000 | N35: =M35+N34 -> 248570 | P35: 3000
B36: 1 | F36: 45129 | G36: 31 | H36: Nilu(Mason)/Salary | I36: Labour | J36: 07/1218 | M36: 25100 | N36: =M36+N35 -> 273670
B37: 1 | F37: 45131 | G37: 32 | H37: Cement Bag 06 Nr | I37: Material | J37: 07/1227 | M37: 12600 | N37: =M37+N36 -> 286270
B38: 1 | F38: 45131 | G38: 33 | H38: Sand Cube 01 | I38: Material | J38: 07/1228 | M38: 15000 | N38: =M38+N37 -> 301270
B39: 1 | F39: 45131 | G39: 34 | H39: 3/4" Metal Cube 01 | I39: Material | J39: 07/1229 | M39: 9500 | N39: =M39+N38 -> 310770
B40: 1 | F40: 45134 | G40: 35 | H40: Ajantha(Mason)/Advance | I40: Labour | J40: 07/1237 | M40: 2000 | N40: =M40+N39 -> 312770
B41: 1 | F41: 45136 | G41: 36 | H41: Ajantha(Mason)/Advance | I41: Labour | J41: 07/1241 | M41: 41600 | N41: =M41+N40 -> 354370
B42: 1 | F42: 45133 | G42: 37 | H42: Linko Construction | I42: Machinery | J42: 07/1242 | M42: 1000 | N42: =M42+N41 -> 355370
...
